<?xml version='1.0' encoding='utf-8'?>
<robot name="l3">
  <mujoco>
    <compiler
    meshdir="../meshes"
    balanceinertia="true"
    discardvisual="false"/>
  </mujoco>  
  <link name="base_link">
    <inertial>
      <origin xyz="0.0084431 0.0017506 -0.15762" rpy="0 0 0" />
      <mass value="12" />
      <inertia ixx="0.1567" ixy="0.0007" ixz="-0.0013" iyy="0.136" iyz="0.0014" izz="0.0814" />
    </inertial>
    <visual>
      <origin xyz="0 0 0" rpy="0 0 0" />
      <geometry>
        <mesh filename="package://xbot_description/l3/meshes/base_link.STL" />
      </geometry>
      <material name="">
        <color rgba="0.75294 0.75294 0.75294 1" />
      </material>
    </visual>
    <collision>
      <origin xyz="0 0 0" rpy="0 0 0" />
      <geometry>
        <mesh filename="package://xbot_description/l3/meshes/base_link.STL" />
      </geometry>
    </collision>
  </link>
  <link name="neck_yaw_link">
    <inertial>
      <origin xyz="0.022925 0.0064532 0.1431" rpy="0 0 0" />
      <mass value="0.64" />
      <inertia ixx="0.0007" ixy="7.2177E-07" ixz="6.2158E-05" iyy="0.00076082" iyz="-1.0259E-07" izz="0.00066743" />
    </inertial>
    <visual>
      <origin xyz="0 0 0" rpy="0 0 0" />
      <geometry>
        <mesh filename="package://xbot_description/l3/meshes/neck_yaw_link.STL" />
      </geometry>
      <material name="">
        <color rgba="0.75294 0.75294 0.75294 1" />
      </material>
    </visual>
    <collision>
      <origin xyz="0 0 0" rpy="0 0 0" />
      <geometry>
        <mesh filename="package://xbot_description/l3/meshes/neck_yaw_link.STL" />
      </geometry>
    </collision>
  </link>
  <joint name="neck_yaw_joint" type="revolute">
    <origin xyz="0 0 0.2365" rpy="0 0 0" />
    <parent link="base_link" />
    <child link="neck_yaw_link" />
    <axis xyz="0.0 0.0 1.0" />
    <limit lower="-1.57" upper="1.57" effort="35.0" velocity="4.19" />
    <dynamics friction="1.111" />
  </joint>
  <link name="neck_pitch_link">
    <inertial>
      <origin xyz="-0.011299 0.00058037 0.091458" rpy="0 0 0" />
      <mass value="1.15" />
      <inertia ixx="0.0068" ixy="5.8684E-07" ixz="-0.001" iyy="0.008" iyz="-1.8384E-06" izz="0.0067" />
    </inertial>
    <visual>
      <origin xyz="0 0 0" rpy="0 0 0" />
      <geometry>
        <mesh filename="package://xbot_description/l3/meshes/neck_pitch_link.STL" />
      </geometry>
      <material name="">
        <color rgba="0.75294 0.75294 0.75294 1" />
      </material>
    </visual>
    <collision>
      <origin xyz="0 0 0" rpy="0 0 0" />
      <geometry>
        <mesh filename="package://xbot_description/l3/meshes/neck_pitch_link.STL" />
      </geometry>
    </collision>
  </link>
  <joint name="neck_pitch_joint" type="revolute">
    <origin xyz="0.032 0 0.1535" rpy="0 0 0" />
    <parent link="neck_yaw_link" />
    <child link="neck_pitch_link" />
    <axis xyz="0.0 1.0 0.0" />
    <limit lower="-0.17" upper="0.54" effort="35.0" velocity="4.19" />
    <dynamics friction="1.111" />
  </joint>
  <link name="mic_link">
    <inertial>
      <origin xyz="4.0559559438211E-15 5.0626883046772E-14 0.00250000000000028" rpy="0 0 0" />
      <mass value="1.375E-08" />
      <inertia ixx="5.72916666666666E-14" ixy="-3.25716998007038E-30" ixz="-4.41640888106544E-30" iyy="5.72916666666666E-14" iyz="1.14211830008865E-30" izz="5.72916666666666E-14" />
    </inertial>
    <visual>
      <origin xyz="0 0 0" rpy="0 0 0" />
      <geometry>
        <mesh filename="package://xbot_description/l3/meshes/mic_link.STL" />
      </geometry>
      <material name="">
        <color rgba="1 0.549019607843137 0 1" />
      </material>
    </visual>
    <collision>
      <origin xyz="0 0 0" rpy="0 0 0" />
      <geometry>
        <mesh filename="package://xbot_description/l3/meshes/mic_link.STL" />
      </geometry>
    </collision>
  </link>
  <joint name="mic_joint" type="fixed">
    <origin xyz="-0.032 0 0.18725" rpy="0 0 0" />
    <parent link="neck_pitch_link" />
    <child link="mic_link" />
    <axis xyz="0.0 0.0 0.0" />
  </joint>
  <link name="head_rs_link">
    <inertial>
      <origin xyz="0.047424 0.00014285 -0.0082421" rpy="0 0 0" />
      <mass value="0.076907" />
      <inertia ixx="8.6659E-06" ixy="9.2769E-08" ixz="-9.1747E-08" iyy="9.4298E-05" iyz="9.0197E-08" izz="9.4996E-05" />
    </inertial>
    <visual>
      <origin xyz="0 0 0" rpy="0 0 0" />
      <geometry>
        <mesh filename="package://xbot_description/l3/meshes/head_rs_link.STL" />
      </geometry>
      <material name="">
        <color rgba="0.25098 0.25098 0.25098 1" />
      </material>
    </visual>
    <collision>
      <origin xyz="0 0 0" rpy="0 0 0" />
      <geometry>
        <mesh filename="package://xbot_description/l3/meshes/head_rs_link.STL" />
      </geometry>
    </collision>
  </link>
  <joint name="head_rs_joint" type="fixed">
    <origin xyz="0.070728434602136 0.0475000000000512 0.127173847577293" rpy="-2.0943951023932 0 -1.57079632679506" />
    <parent link="neck_pitch_link" />
    <child link="head_rs_link" />
    <axis xyz="0.0 0.0 0.0" />
  </joint>
  <link name="left_arm_base_link">
    <inertial>
      <origin xyz="0.00016424 0.033422 -0.0016166" rpy="0 0 0" />
      <mass value="0.9172" />
      <inertia ixx="0.0009" ixy="-6.5718E-07" ixz="4.9197E-07" iyy="0.0009" iyz="-3.689E-06" izz="0.0009" />
    </inertial>
    <visual>
      <origin xyz="0 0 0" rpy="0 0 0" />
      <geometry>
        <mesh filename="package://xbot_description/l3/meshes/left_arm_base_link.STL" />
      </geometry>
      <material name="">
        <color rgba="0.75294 0.75294 0.75294 1" />
      </material>
    </visual>
    <collision>
      <origin xyz="0 0 0" rpy="0 0 0" />
      <geometry>
        <mesh filename="package://xbot_description/l3/meshes/left_arm_base_link.STL" />
      </geometry>
    </collision>
  </link>
  <joint name="left_arm_base_joint" type="fixed">
    <origin xyz="0 0.112 0.2365" rpy="0 0 0" />
    <parent link="base_link" />
    <child link="left_arm_base_link" />
    <axis xyz="0.0 0.0 0.0" />
    <limit lower="0" upper="0" effort="0" velocity="0" />
  </joint>
  <link name="left_shoulder_pitch_link">
    <inertial>
      <origin xyz="-0.010548 0.12346 -0.021666" rpy="0 0 0" />
      <mass value="1.1618" />
      <inertia ixx="0.002" ixy="-0.0001" ixz="2.6138E-07" iyy="0.0015" iyz="-0.0002" izz="0.0019146" />
    </inertial>
    <visual>
      <origin xyz="0 0 0" rpy="0 0 0" />
      <geometry>
        <mesh filename="package://xbot_description/l3/meshes/left_shoulder_pitch_link.STL" />
      </geometry>
      <material name="">
        <color rgba="0.75294 0.75294 0.75294 1" />
      </material>
    </visual>
    <collision>
      <origin xyz="0 0 0" rpy="0 0 0" />
      <geometry>
        <mesh filename="package://xbot_description/l3/meshes/left_shoulder_pitch_link.STL" />
      </geometry>
    </collision>
  </link>
  <joint name="left_shoulder_pitch_joint" type="revolute">
    <origin xyz="0 0 0" rpy="0 0 0" />
    <parent link="left_arm_base_link" />
    <child link="left_shoulder_pitch_link" />
    <axis xyz="0.0 1.0 0.0" />
    <limit lower="-2.79" upper="2.79" effort="110.0" velocity="4.19" />
    <dynamics friction="1.222" />
  </joint>
  <link name="left_shoulder_roll_link">
    <inertial>
      <origin xyz="-0.0010652 -0.00016594 -0.091811" rpy="0 0 0" />
      <mass value="1.1852" />
      <inertia ixx="0.0029" ixy="-2.4124E-06" ixz="-7.7624E-06" iyy="0.0029" iyz="1.0466E-05" izz="0.0016" />
    </inertial>
    <visual>
      <origin xyz="0 0 0" rpy="0 0 0" />
      <geometry>
        <mesh filename="package://xbot_description/l3/meshes/left_shoulder_roll_link.STL" />
      </geometry>
      <material name="">
        <color rgba="0.75294 0.75294 0.75294 1" />
      </material>
    </visual>
    <collision>
      <origin xyz="0 0 0" rpy="0 0 0" />
      <geometry>
        <mesh filename="package://xbot_description/l3/meshes/left_shoulder_roll_link.STL" />
      </geometry>
    </collision>
  </link>
  <joint name="left_shoulder_roll_joint" type="revolute">
    <origin xyz="0 0.133 -0.025" rpy="0 0 0" />
    <parent link="left_shoulder_pitch_link" />
    <child link="left_shoulder_roll_link" />
    <axis xyz="1.0 0.0 0.0" />
    <limit lower="-0.24" upper="1.83" effort="110.0" velocity="4.19" />
    <dynamics friction="1.222" />
  </joint>
  <link name="left_arm_yaw_link">
    <inertial>
      <origin xyz="0.0033229 -0.0016876 -0.18801" rpy="0 0 0" />
      <mass value="0.354" />
      <inertia ixx="0.0011" ixy="3.633E-07" ixz="0.00013546" iyy="0.001" iyz="1.2618E-06" izz="0.0007" />
    </inertial>
    <visual>
      <origin xyz="0 0 0" rpy="0 0 0" />
      <geometry>
        <mesh filename="package://xbot_description/l3/meshes/left_arm_yaw_link.STL" />
      </geometry>
      <material name="">
        <color rgba="0.75294 0.75294 0.75294 1" />
      </material>
    </visual>
    <collision>
      <origin xyz="0 0 0" rpy="0 0 0" />
      <geometry>
        <mesh filename="package://xbot_description/l3/meshes/left_arm_yaw_link.STL" />
      </geometry>
    </collision>
  </link>
  <joint name="left_arm_yaw_joint" type="revolute">
    <origin xyz="0 0 0" rpy="0 0 0" />
    <parent link="left_shoulder_roll_link" />
    <child link="left_arm_yaw_link" />
    <axis xyz="0.0 0.0 1.0" />
    <limit lower="-2.79" upper="2.79" effort="110.0" velocity="4.19" />
    <dynamics friction="1.222" />
  </joint>
  <link name="left_elbow_pitch_link">
    <inertial>
      <origin xyz="-0.0079717 -0.0068363 -0.045353" rpy="0 0 0" />
      <mass value="1.567" />
      <inertia ixx="0.0048" ixy="-0.0001" ixz="0.0006" iyy="0.0048" iyz="0.0004" izz="0.0016" />
    </inertial>
    <visual>
      <origin xyz="0 0 0" rpy="0 0 0" />
      <geometry>
        <mesh filename="package://xbot_description/l3/meshes/left_elbow_pitch_link.STL" />
      </geometry>
      <material name="">
        <color rgba="0.75294 0.75294 0.75294 1" />
      </material>
    </visual>
    <collision>
      <origin xyz="0 0 0" rpy="0 0 0" />
      <geometry>
        <mesh filename="package://xbot_description/l3/meshes/left_elbow_pitch_link.STL" />
      </geometry>
    </collision>
  </link>
  <joint name="left_elbow_pitch_joint" type="revolute">
    <origin xyz="0.016 0 -0.232" rpy="0 0 0" />
    <parent link="left_arm_yaw_link" />
    <child link="left_elbow_pitch_link" />
    <axis xyz="0.0 1.0 0.0" />
    <limit lower="-2.36" upper="0.79" effort="110.0" velocity="4.19" />
    <dynamics friction="1.222" />
  </joint>
  <link name="left_elbow_yaw_link">
    <inertial>
      <origin xyz="3.0416E-06 -0.001965 0.030234" rpy="0 0 0" />
      <mass value="0.1556" />
      <inertia ixx="0.00019055" ixy="5.6249E-08" ixz="-2.3188E-08" iyy="0.0001" iyz="-2.1005E-06" izz="0.0002" />
    </inertial>
    <visual>
      <origin xyz="0 0 0" rpy="0 0 0" />
      <geometry>
        <mesh filename="package://xbot_description/l3/meshes/left_elbow_yaw_link.STL" />
      </geometry>
      <material name="">
        <color rgba="0.75294 0.75294 0.75294 1" />
      </material>
    </visual>
    <collision>
      <origin xyz="0 0 0" rpy="0 0 0" />
      <geometry>
        <mesh filename="package://xbot_description/l3/meshes/left_elbow_yaw_link.STL" />
      </geometry>
    </collision>
  </link>
  <joint name="left_elbow_yaw_joint" type="revolute">
    <origin xyz="-0.016 0 -0.166" rpy="0 0 0" />
    <parent link="left_elbow_pitch_link" />
    <child link="left_elbow_yaw_link" />
    <axis xyz="0.0 0.0 1.0" />
    <limit lower="-2.62" upper="2.62" effort="35.0" velocity="4.19" />
    <dynamics friction="1.111" />
  </joint>
  <link name="left_wrist_pitch_link">
    <inertial>
      <origin xyz="-0.00027663 -0.0069214 -0.0061943" rpy="0 0 0" />
      <mass value="0.625" />
      <inertia ixx="0.0006" ixy="1.3182E-08" ixz="-8.9769E-07" iyy="0.0006" iyz="7.1645E-06" izz="0.0004" />
    </inertial>
    <visual>
      <origin xyz="0 0 0" rpy="0 0 0" />
      <geometry>
        <mesh filename="package://xbot_description/l3/meshes/left_wrist_pitch_link.STL" />
      </geometry>
      <material name="">
        <color rgba="0.75294 0.75294 0.75294 1" />
      </material>
    </visual>
    <collision>
      <origin xyz="0 0 0" rpy="0 0 0" />
      <geometry>
        <mesh filename="package://xbot_description/l3/meshes/left_wrist_pitch_link.STL" />
      </geometry>
    </collision>
  </link>
  <joint name="left_wrist_pitch_joint" type="revolute">
    <origin xyz="0 0 0" rpy="0 0 0" />
    <parent link="left_elbow_yaw_link" />
    <child link="left_wrist_pitch_link" />
    <axis xyz="0.0 1.0 0.0" />
    <limit lower="-1.57" upper="1.57" effort="35.0" velocity="4.19" />
    <dynamics friction="1.111" />
  </joint>
  <link name="left_wrist_roll_link">
    <inertial>
      <origin xyz="-0.0075938 0.00010133 -0.00064617" rpy="0 0 0" />
      <mass value="0.58" />
      <inertia ixx="0.0003" ixy="-1.0565E-06" ixz="5.2302E-07" iyy="0.00027887" iyz="8.2448E-07" izz="0.0003" />
    </inertial>
    <visual>
      <origin xyz="0 0 0" rpy="0 0 0" />
      <geometry>
        <mesh filename="package://xbot_description/l3/meshes/left_wrist_roll_link.STL" />
      </geometry>
      <material name="">
        <color rgba="0.75294 0.75294 0.75294 1" />
      </material>
    </visual>
    <collision>
      <origin xyz="0 0 0" rpy="0 0 0" />
      <geometry>
        <mesh filename="package://xbot_description/l3/meshes/left_wrist_roll_link.STL" />
      </geometry>
    </collision>
  </link>
  <joint name="left_wrist_roll_joint" type="revolute">
    <origin xyz="0 0 -0.065" rpy="0 0 0" />
    <parent link="left_wrist_pitch_link" />
    <child link="left_wrist_roll_link" />
    <axis xyz="1.0 0.0 0.0" />
    <limit lower="-1.75" upper="1.75" effort="35.0" velocity="4.19" />
    <dynamics friction="1.111" />
  </joint>
  <link name="left_hand_base_link">
    <inertial>
      <origin xyz="-9.28058448083809E-16 0 0.0025" rpy="0 0 0" />
      <mass value="1.375E-08" />
      <inertia ixx="5.72916666666668E-14" ixy="-1.23935247990971E-29" ixz="7.41774071275437E-29" iyy="5.72916666666668E-14" iyz="-1.21732704397467E-31" izz="5.72916666666668E-14" />
    </inertial>
    <visual>
      <origin xyz="0 0 0" rpy="0 0 0" />
      <geometry>
        <mesh filename="package://xbot_description/l3/meshes/left_hand_base_link.STL" />
      </geometry>
      <material name="">
        <color rgba="1 0.549019607843137 0 1" />
      </material>
    </visual>
    <collision>
      <origin xyz="0 0 0" rpy="0 0 0" />
      <geometry>
        <mesh filename="package://xbot_description/l3/meshes/left_hand_base_link.STL" />
      </geometry>
    </collision>
  </link>
  <joint name="left_hand_base_joint" type="fixed">
    <origin xyz="0 0 -0.0400000000000008" rpy="0 0 0" />
    <parent link="left_wrist_roll_link" />
    <child link="left_hand_base_link" />
    <axis xyz="0.0 0.0 0.0" />
  </joint>
  <link name="left_hand_ee_link">
    <inertial>
      <origin xyz="-1.69621793423315E-16 -7.83468649371551E-16 0" rpy="0 0 0" />
      <mass value="3.53429173528852E-08" />
      <inertia ixx="3.97607820219958E-14" ixy="2.1306062234609E-28" ixz="-6.0696092927852E-27" iyy="9.35114688295087E-14" iyz="2.40522431637656E-41" izz="9.35114688295086E-14" />
    </inertial>
    <visual>
      <origin xyz="0 0 0" rpy="0 0 0" />
      <geometry>
        <mesh filename="package://xbot_description/l3/meshes/left_hand_ee_link.STL" />
      </geometry>
      <material name="">
        <color rgba="0.698039215686274 0.698039215686274 0.698039215686274 1" />
      </material>
    </visual>
    <collision>
      <origin xyz="0 0 0" rpy="0 0 0" />
      <geometry>
        <mesh filename="package://xbot_description/l3/meshes/left_hand_ee_link.STL" />
      </geometry>
    </collision>
  </link>
  <joint
    name="left_hand_ee_joint"
    type="fixed">
    <origin
      xyz="0 0 -0.06"
      rpy="3.1416 0 0" />
    <parent
      link="left_hand_link" />
    <child
      link="left_hand_ee_link" />
    <axis
      xyz="0 0 0" />
  </joint>  
  <link name="right_arm_base_link">
    <inertial>
      <origin xyz="-0.00016424 -0.033422 -0.0016166" rpy="0 0 0" />
      <mass value="0.9172" />
      <inertia ixx="0.0009" ixy="-6.5718E-07" ixz="-4.9197E-07" iyy="0.0009" iyz="3.689E-06" izz="0.0009" />
    </inertial>
    <visual>
      <origin xyz="0 0 0" rpy="0 0 0" />
      <geometry>
        <mesh filename="package://xbot_description/l3/meshes/right_arm_base_link.STL" />
      </geometry>
      <material name="">
        <color rgba="0.75294 0.75294 0.75294 1" />
      </material>
    </visual>
    <collision>
      <origin xyz="0 0 0" rpy="0 0 0" />
      <geometry>
        <mesh filename="package://xbot_description/l3/meshes/right_arm_base_link.STL" />
      </geometry>
    </collision>
  </link>
  <joint name="right_arm_base_joint" type="fixed">
    <origin xyz="0 -0.112 0.2365" rpy="0 0 0" />
    <parent link="base_link" />
    <child link="right_arm_base_link" />
    <axis xyz="0.0 0.0 0.0" />
  </joint>
  <link name="right_shoulder_pitch_link">
    <inertial>
      <origin xyz="-0.010534 -0.1231 -0.021409" rpy="0 0 0" />
      <mass value="1.1634" />
      <inertia ixx="0.0019" ixy="-1.4756E-06" ixz="5.7053E-07" iyy="0.0015" iyz="-6.7172E-05" izz="0.0019103" />
    </inertial>
    <visual>
      <origin xyz="0 0 0" rpy="0 0 0" />
      <geometry>
        <mesh filename="package://xbot_description/l3/meshes/right_shoulder_pitch_link.STL" />
      </geometry>
      <material name="">
        <color rgba="0.75294 0.75294 0.75294 1" />
      </material>
    </visual>
    <collision>
      <origin xyz="0 0 0" rpy="0 0 0" />
      <geometry>
        <mesh filename="package://xbot_description/l3/meshes/right_shoulder_pitch_link.STL" />
      </geometry>
    </collision>
  </link>
  <joint name="right_shoulder_pitch_joint" type="revolute">
    <origin xyz="0 0 0" rpy="0 0 0" />
    <parent link="right_arm_base_link" />
    <child link="right_shoulder_pitch_link" />
    <axis xyz="0.0 1.0 0.0" />
    <limit lower="-2.79" upper="2.79" effort="110.0" velocity="4.19" />
    <dynamics friction="1.222" />
  </joint>
  <link name="right_shoulder_roll_link">
    <inertial>
      <origin xyz="-0.001069 2.5863E-05 -0.09185" rpy="0 0 0" />
      <mass value="1.1852" />
      <inertia ixx="0.0029" ixy="-2.6029E-06" ixz="-7.8051E-06" iyy="0.0029" iyz="-1.2426E-05" izz="0.0016" />
    </inertial>
    <visual>
      <origin xyz="0 0 0" rpy="0 0 0" />
      <geometry>
        <mesh filename="package://xbot_description/l3/meshes/right_shoulder_roll_link.STL" />
      </geometry>
      <material name="">
        <color rgba="0.75294 0.75294 0.75294 1" />
      </material>
    </visual>
    <collision>
      <origin xyz="0 0 0" rpy="0 0 0" />
      <geometry>
        <mesh filename="package://xbot_description/l3/meshes/right_shoulder_roll_link.STL" />
      </geometry>
    </collision>
  </link>
  <joint name="right_shoulder_roll_joint" type="revolute">
    <origin xyz="0 -0.133 -0.025" rpy="0 0 0" />
    <parent link="right_shoulder_pitch_link" />
    <child link="right_shoulder_roll_link" />
    <axis xyz="1.0 0.0 0.0" />
    <limit lower="-1.83" upper="0.24" effort="110.0" velocity="4.19" />
    <dynamics friction="1.222" />
  </joint>
  <link name="right_arm_yaw_link">
    <inertial>
      <origin xyz="0.0018254 0.0021888 -0.18116" rpy="0 0 0" />
      <mass value="0.35384" />
      <inertia ixx="0.0011" ixy="-1.9189E-07" ixz="6.9862E-05" iyy="0.001" iyz="-6.1562E-07" izz="0.0007" />
    </inertial>
    <visual>
      <origin xyz="0 0 0" rpy="0 0 0" />
      <geometry>
        <mesh filename="package://xbot_description/l3/meshes/right_arm_yaw_link.STL" />
      </geometry>
      <material name="">
        <color rgba="0.75294 0.75294 0.75294 1" />
      </material>
    </visual>
    <collision>
      <origin xyz="0 0 0" rpy="0 0 0" />
      <geometry>
        <mesh filename="package://xbot_description/l3/meshes/right_arm_yaw_link.STL" />
      </geometry>
    </collision>
  </link>
  <joint name="right_arm_yaw_joint" type="revolute">
    <origin xyz="0 0 0" rpy="0 0 0" />
    <parent link="right_shoulder_roll_link" />
    <child link="right_arm_yaw_link" />
    <axis xyz="0.0 0.0 1.0" />
    <limit lower="-2.79" upper="2.79" effort="110.0" velocity="4.19" />
    <dynamics friction="1.222" />
  </joint>
  <link name="right_elbow_pitch_link">
    <inertial>
      <origin xyz="-0.008079 0.0068364 -0.045351" rpy="0 0 0" />
      <mass value="1.8745" />
      <inertia ixx="0.0048" ixy="0.0001" ixz="0.0005" iyy="0.0048" iyz="0.0004" izz="0.0016" />
    </inertial>
    <visual>
      <origin xyz="0 0 0" rpy="0 0 0" />
      <geometry>
        <mesh filename="package://xbot_description/l3/meshes/right_elbow_pitch_link.STL" />
      </geometry>
      <material name="">
        <color rgba="0.75294 0.75294 0.75294 1" />
      </material>
    </visual>
    <collision>
      <origin xyz="0 0 0" rpy="0 0 0" />
      <geometry>
        <mesh filename="package://xbot_description/l3/meshes/right_elbow_pitch_link.STL" />
      </geometry>
    </collision>
  </link>
  <joint name="right_elbow_pitch_joint" type="revolute">
    <origin xyz="0.016 0 -0.232" rpy="0 0 0" />
    <parent link="right_arm_yaw_link" />
    <child link="right_elbow_pitch_link" />
    <axis xyz="0.0 1.0 0.0" />
    <limit lower="-2.36" upper="0.79" effort="110.0" velocity="4.19" />
    <dynamics friction="1.222" />
  </joint>
  <link name="right_elbow_yaw_link">
    <inertial>
      <origin xyz="-3.0641E-06 0.001965 0.030234" rpy="0 0 0" />
      <mass value="0.1556" />
      <inertia ixx="0.00019055" ixy="5.6249E-08" ixz="2.3188E-08" iyy="0.0001" iyz="2.1005E-06" izz="0.0002" />
    </inertial>
    <visual>
      <origin xyz="0 0 0" rpy="0 0 0" />
      <geometry>
        <mesh filename="package://xbot_description/l3/meshes/right_elbow_yaw_link.STL" />
      </geometry>
      <material name="">
        <color rgba="0.75294 0.75294 0.75294 1" />
      </material>
    </visual>
    <collision>
      <origin xyz="0 0 0" rpy="0 0 0" />
      <geometry>
        <mesh filename="package://xbot_description/l3/meshes/right_elbow_yaw_link.STL" />
      </geometry>
    </collision>
  </link>
  <joint name="right_elbow_yaw_joint" type="revolute">
    <origin xyz="-0.016 0 -0.166" rpy="0 0 0" />
    <parent link="right_elbow_pitch_link" />
    <child link="right_elbow_yaw_link" />
    <axis xyz="0.0 0.0 1.0" />
    <limit lower="-2.62" upper="2.62" effort="35.0" velocity="4.19" />
    <dynamics friction="1.111" />
  </joint>
  <link name="right_wrist_pitch_link">
    <inertial>
      <origin xyz="-0.00021408 0.007602 -0.0035533" rpy="0 0 0" />
      <mass value="0.625" />
      <inertia ixx="0.0006" ixy="-2.5664E-07" ixz="-2.1058E-06" iyy="0.0006" iyz="-3.1746E-06" izz="0.0004" />
    </inertial>
    <visual>
      <origin xyz="0 0 0" rpy="0 0 0" />
      <geometry>
        <mesh filename="package://xbot_description/l3/meshes/right_wrist_pitch_link.STL" />
      </geometry>
      <material name="">
        <color rgba="0.75294 0.75294 0.75294 1" />
      </material>
    </visual>
    <collision>
      <origin xyz="0 0 0" rpy="0 0 0" />
      <geometry>
        <mesh filename="package://xbot_description/l3/meshes/right_wrist_pitch_link.STL" />
      </geometry>
    </collision>
  </link>
  <joint name="right_wrist_pitch_joint" type="revolute">
    <origin xyz="0 0 0" rpy="0 0 0" />
    <parent link="right_elbow_yaw_link" />
    <child link="right_wrist_pitch_link" />
    <axis xyz="0.0 1.0 0.0" />
    <limit lower="-1.57" upper="1.57" effort="35.0" velocity="4.19" />
    <dynamics friction="1.111" />
  </joint>
  <link name="right_wrist_roll_link">
    <inertial>
      <origin xyz="-0.0075938 0.00010133 -0.00064617" rpy="0 0 0" />
      <mass value="0.584" />
      <inertia ixx="0.0003" ixy="-1.0565E-06" ixz="5.2303E-07" iyy="0.00027887" iyz="8.2448E-07" izz="0.00029" />
    </inertial>
    <visual>
      <origin xyz="0 0 0" rpy="0 0 0" />
      <geometry>
        <mesh filename="package://xbot_description/l3/meshes/right_wrist_roll_link.STL" />
      </geometry>
      <material name="">
        <color rgba="0.75294 0.75294 0.75294 1" />
      </material>
    </visual>
    <collision>
      <origin xyz="0 0 0" rpy="0 0 0" />
      <geometry>
        <mesh filename="package://xbot_description/l3/meshes/right_wrist_roll_link.STL" />
      </geometry>
    </collision>
  </link>
  <joint name="right_wrist_roll_joint" type="revolute">
    <origin xyz="0 0 -0.065" rpy="0 0 0" />
    <parent link="right_wrist_pitch_link" />
    <child link="right_wrist_roll_link" />
    <axis xyz="1.0 0.0 0.0" />
    <limit lower="-1.75" upper="1.75" effort="35.0" velocity="4.19" />
    <dynamics friction="1.111" />
  </joint>
  <link name="right_hand_base_link">
    <inertial>
      <origin xyz="2.99955512309407E-14 -2.63677968348475E-15 0.0024999999999997" rpy="0 0 0" />
      <mass value="1.375E-08" />
      <inertia ixx="5.72916666666668E-14" ixy="-1.23935247990971E-29" ixz="7.41774071275437E-29" iyy="5.72916666666668E-14" iyz="-1.21732704397467E-31" izz="5.72916666666668E-14" />
    </inertial>
    <visual>
      <origin xyz="0 0 0" rpy="0 0 0" />
      <geometry>
        <mesh filename="package://xbot_description/l3/meshes/right_hand_base_link.STL" />
      </geometry>
      <material name="">
        <color rgba="1 0.549019607843137 0 1" />
      </material>
    </visual>
    <collision>
      <origin xyz="0 0 0" rpy="0 0 0" />
      <geometry>
        <mesh filename="package://xbot_description/l3/meshes/right_hand_base_link.STL" />
      </geometry>
    </collision>
  </link>
  <joint name="right_hand_base_joint" type="fixed">
    <origin xyz="0 0 -0.0399999999999996" rpy="0 0 0" />
    <parent link="right_wrist_roll_link" />
    <child link="right_hand_base_link" />
    <axis xyz="0.0 0.0 0.0" />
  </joint>
  <link name="right_hand_ee_link">
    <inertial>
      <origin xyz="-6.98527914532583E-15 -2.72004641033163E-15 0.00249999999999817" rpy="0 0 0" />
      <mass value="1.375E-08" />
      <inertia ixx="5.72916666666668E-14" ixy="-1.23935247990961E-29" ixz="-1.80141577278528E-28" iyy="5.72916666666668E-14" iyz="-4.55124076831941E-30" izz="5.72916666666668E-14" />
    </inertial>
    <visual>
      <origin xyz="0 0 0" rpy="0 0 0" />
      <geometry>
        <mesh filename="package://xbot_description/l3/meshes/right_hand_ee_link.STL" />
      </geometry>
      <material name="">
        <color rgba="1 0.549019607843137 0 1" />
      </material>
    </visual>
    <collision>
      <origin xyz="0 0 0" rpy="0 0 0" />
      <geometry>
        <mesh filename="package://xbot_description/l3/meshes/right_hand_ee_link.STL" />
      </geometry>
    </collision>
  </link>
    <joint
    name="right_hand_ee_joint"
    type="fixed">
    <origin
      xyz="0 0 -0.065"
      rpy="3.1416 0 0" />
    <parent
      link="right_hand_link" />
    <child
      link="right_hand_ee_link" />
    <axis
      xyz="0 0 0" />
  </joint>

  <link name="waist_base_link">
    <inertial>
      <origin xyz="-0.00086082 5.1861E-08 -0.050183" rpy="0 0 0" />
      <mass value="1.8301" />
      <inertia ixx="0.007" ixy="-1.1548E-06" ixz="-2.5479E-05" iyy="0.0018" iyz="1.7553E-10" izz="0.0074" />
    </inertial>
    <visual>
      <origin xyz="0 0 0" rpy="0 0 0" />
      <geometry>
        <mesh filename="package://xbot_description/l3/meshes/waist_base_link.STL" />
      </geometry>
      <material name="">
        <color rgba="0.75294 0.75294 0.75294 1" />
      </material>
    </visual>
    <collision>
      <origin xyz="0 0 0" rpy="0 0 0" />
      <geometry>
        <mesh filename="package://xbot_description/l3/meshes/waist_base_link.STL" />
      </geometry>
    </collision>
  </link>
  <joint name="waist_base_joint" type="fixed">
    <origin xyz="0 0 0" rpy="0 0 0" />
    <parent link="base_link" />
    <child link="waist_base_link" />
    <axis xyz="0.0 0.0 0.0" />
  </joint>
  <link name="waist_pitch_link">
    <inertial>
      <origin xyz="-3.9493E-09 -5.5675E-09 -5.9673E-05" rpy="0 0 0" />
      <mass value="0.068747" />
      <inertia ixx="5.3442E-06" ixy="-3.6643E-13" ixz="2.3097E-12" iyy="5.5342E-06" iyz="-9.5786E-13" izz="8.9493E-06" />
    </inertial>
    <visual>
      <origin xyz="0 0 0" rpy="0 0 0" />
      <geometry>
        <mesh filename="package://xbot_description/l3/meshes/waist_pitch_link.STL" />
      </geometry>
      <material name="">
        <color rgba="0.75294 0.75294 0.75294 1" />
      </material>
    </visual>
    <collision>
      <origin xyz="0 0 0" rpy="0 0 0" />
      <geometry>
        <mesh filename="package://xbot_description/l3/meshes/waist_pitch_link.STL" />
      </geometry>
    </collision>
  </link>
  <joint name="waist_pitch_joint" type="revolute">
    <origin xyz="0 0 -0.1015" rpy="0 0 0" />
    <parent link="waist_base_link" />
    <child link="waist_pitch_link" />
    <axis xyz="0.0 1.0 0.0" />
    <limit lower="-1.05" upper="0.09" effort="220.0" velocity="4.19" />
    <dynamics friction="1.222" />
  </joint>
  <link name="waist_roll_link">
    <inertial>
      <origin xyz="0.0028204 2.6985E-09 -0.017965" rpy="0 0 0" />
      <mass value="0.15785" />
      <inertia ixx="0.0001" ixy="1.7947E-10" ixz="1.1992E-06" iyy="0.0001" iyz="7.5361E-11" izz="0.0001" />
    </inertial>
    <visual>
      <origin xyz="0 0 0" rpy="0 0 0" />
      <geometry>
        <mesh filename="package://xbot_description/l3/meshes/waist_roll_link.STL" />
      </geometry>
      <material name="">
        <color rgba="0.75294 0.75294 0.75294 1" />
      </material>
    </visual>
    <collision>
      <origin xyz="0 0 0" rpy="0 0 0" />
      <geometry>
        <mesh filename="package://xbot_description/l3/meshes/waist_roll_link.STL" />
      </geometry>
    </collision>
  </link>
  <joint name="waist_roll_joint" type="revolute">
    <origin xyz="0 0 0" rpy="0 0 0" />
    <parent link="waist_pitch_link" />
    <child link="waist_roll_link" />
    <axis xyz="1.0 0.0 0.0" />
    <limit lower="-0.26" upper="0.26" effort="220.0" velocity="4.19" />
    <dynamics friction="1.222" />
  </joint>
  <link name="waist_yaw_link">
    <inertial>
      <origin xyz="-0.064098 -0.00018359 -0.074077" rpy="0 0 0" />
      <mass value="5.778" />
      <inertia ixx="0.068" ixy="4.0449E-06" ixz="0.0017" iyy="0.0188" iyz="-0.0002" izz="0.0756" />
    </inertial>
    <visual>
      <origin xyz="0 0 0" rpy="0 0 0" />
      <geometry>
        <mesh filename="package://xbot_description/l3/meshes/waist_yaw_link.STL" />
      </geometry>
      <material name="">
        <color rgba="0.75294 0.75294 0.75294 1" />
      </material>
    </visual>
    <collision>
      <origin xyz="0 0 0" rpy="0 0 0" />
      <geometry>
        <mesh filename="package://xbot_description/l3/meshes/waist_yaw_link.STL" />
      </geometry>
    </collision>
  </link>
  <joint name="waist_yaw_joint" type="revolute">
    <origin xyz="0 0 0" rpy="0 0 0" />
    <parent link="waist_roll_link" />
    <child link="waist_yaw_link" />
    <axis xyz="0.0 0.0 1.0" />
    <limit lower="-1.57" upper="1.57" effort="110.0" velocity="4.19" />
    <dynamics friction="1.222" />
  </joint>
  <link name="left_hip_roll_link">
    <inertial>
      <origin xyz="-0.0016523 6.6007E-06 0.003973" rpy="0 0 0" />
      <mass value="1.6446" />
      <inertia ixx="0.0023" ixy="-4.1132E-08" ixz="1.953E-05" iyy="0.0024" iyz="-6.1327E-07" izz="0.0029425" />
    </inertial>
    <visual>
      <origin xyz="0 0 0" rpy="0 0 0" />
      <geometry>
        <mesh filename="package://xbot_description/l3/meshes/left_hip_roll_link.STL" />
      </geometry>
      <material name="">
        <color rgba="0.75294 0.75294 0.75294 1" />
      </material>
    </visual>
    <collision>
      <origin xyz="0 0 0" rpy="0 0 0" />
      <geometry>
        <mesh filename="package://xbot_description/l3/meshes/left_hip_roll_link.STL" />
      </geometry>
    </collision>
  </link>
  <joint name="left_hip_roll_joint" type="revolute">
    <origin xyz="0 0.115 -0.079" rpy="0 0 0" />
    <parent link="waist_yaw_link" />
    <child link="left_hip_roll_link" />
    <axis xyz="1.0 0.0 0.0" />
    <limit lower="-0.21" upper="1.22" effort="255.0" velocity="7.28" />
    <dynamics friction="1.444" />
  </joint>
  <link name="left_hip_yaw_link">
    <inertial>
      <origin xyz="-0.00030509 -0.036415 -0.13923" rpy="0 0 0" />
      <mass value="3.9286" />
      <inertia ixx="0.0108" ixy="0.0001" ixz="6.0163E-05" iyy="0.0163" iyz="0.0006" izz="0.0089" />
    </inertial>
    <visual>
      <origin xyz="0 0 0" rpy="0 0 0" />
      <geometry>
        <mesh filename="package://xbot_description/l3/meshes/left_hip_yaw_link.STL" />
      </geometry>
      <material name="">
        <color rgba="0.75294 0.75294 0.75294 1" />
      </material>
    </visual>
    <collision>
      <origin xyz="0 0 0" rpy="0 0 0" />
      <geometry>
        <mesh filename="package://xbot_description/l3/meshes/left_hip_yaw_link.STL" />
      </geometry>
    </collision>
  </link>
  <joint name="left_hip_yaw_joint" type="revolute">
    <origin xyz="0 0 0" rpy="0 0 0" />
    <parent link="left_hip_roll_link" />
    <child link="left_hip_yaw_link" />
    <axis xyz="0.0 0.0 1.0" />
    <limit lower="-0.52" upper="1.22" effort="100" velocity="13.26" />
    <dynamics friction="1.333" />
  </joint>
  <link name="left_hip_pitch_link">
    <inertial>
      <origin xyz="0.0017618 0.037227 -0.029964" rpy="0 0 0" />
      <mass value="4.6841" />
      <inertia ixx="0.0422" ixy="-0.0004" ixz="-0.002" iyy="0.0469" iyz="0.0055" izz="0.0055" />
    </inertial>
    <visual>
      <origin xyz="0 0 0" rpy="0 0 0" />
      <geometry>
        <mesh filename="package://xbot_description/l3/meshes/left_hip_pitch_link.STL" />
      </geometry>
      <material name="">
        <color rgba="1 1 1 1" />
      </material>
    </visual>
    <collision>
      <origin xyz="0 0 0" rpy="0 0 0" />
      <geometry>
        <mesh filename="package://xbot_description/l3/meshes/left_hip_pitch_link.STL" />
      </geometry>
    </collision>
  </link>
  <joint name="left_hip_pitch_joint" type="revolute">
    <origin xyz="0 -0.01 -0.144" rpy="0 -0.5236 0" />
    <parent link="left_hip_yaw_link" />
    <child link="left_hip_pitch_link" />
    <axis xyz="0.0 1.0 0.0" />
    <limit lower="-1.57" upper="1.4" effort="400.0" velocity="24.94" />
    <dynamics friction="1.555" />
  </joint>
  <link name="left_knee_link">
    <inertial>
      <origin xyz="0.019103 -4.8925E-06 -0.11971" rpy="0 0 0" />
      <mass value="2.1362" />
      <inertia ixx="0.018" ixy="-6.9431E-07" ixz="0.0005" iyy="0.018" iyz="0.0001" izz="0.0019" />
    </inertial>
    <visual>
      <origin xyz="0 0 0" rpy="0 0 0" />
      <geometry>
        <mesh filename="package://xbot_description/l3/meshes/left_knee_link.STL" />
      </geometry>
      <material name="">
        <color rgba="1 1 1 1" />
      </material>
    </visual>
    <collision>
      <origin xyz="0 0 0" rpy="0 0 0" />
      <geometry>
        <mesh filename="package://xbot_description/l3/meshes/left_knee_link.STL" />
      </geometry>
    </collision>
  </link>
  <joint name="left_knee_joint" type="revolute">
    <origin xyz="0 0 -0.36" rpy="0 1.0472 0" />
    <parent link="left_hip_pitch_link" />
    <child link="left_knee_link" />
    <axis xyz="0.0 1.0 0.0" />
    <limit lower="-1.1" upper="1.31" effort="400.0" velocity="24.94" />
    <dynamics friction="1.555" />
  </joint>
  <link name="left_ankle_pitch_link">
    <inertial>
      <origin xyz="-0.00077711 1.5934E-09 5.1139E-05" rpy="0 0 0" />
      <mass value="0.080248" />
      <inertia ixx="4.8112E-06" ixy="-3.3221E-13" ixz="-2.5895E-09" iyy="5.5064E-06" iyz="6.6609E-12" izz="6.4137E-06" />
    </inertial>
    <visual>
      <origin xyz="0 0 0" rpy="0 0 0" />
      <geometry>
        <mesh filename="package://xbot_description/l3/meshes/left_ankle_pitch_link.STL" />
      </geometry>
      <material name="">
        <color rgba="1 1 1 1" />
      </material>
    </visual>
    <collision>
      <origin xyz="0 0 0" rpy="0 0 0" />
      <geometry>
        <mesh filename="package://xbot_description/l3/meshes/left_ankle_pitch_link.STL" />
      </geometry>
    </collision>
  </link>
  <joint name="left_ankle_pitch_joint" type="revolute">
    <origin xyz="0 0 -0.36" rpy="0 -0.5236 0" />
    <parent link="left_knee_link" />
    <child link="left_ankle_pitch_link" />
    <axis xyz="0.0 1.0 0.0" />
    <limit lower="-0.66" upper="1.22" effort="100.0" velocity="13.26" />
    <dynamics friction="0.666" />
  </joint>
  <link name="left_ankle_roll_link">
    <inertial>
      <origin xyz="0.035309 -1.4216E-06 -0.045803" rpy="0 0 0" />
      <mass value="0.85281" />
      <inertia ixx="0.0006" ixy="1.1088E-07" ixz="-0.0003" iyy="0.004" iyz="-1.2805E-08" izz="0.0042" />
    </inertial>
    <visual>
      <origin xyz="0 0 0" rpy="0 0 0" />
      <geometry>
        <mesh filename="package://xbot_description/l3/meshes/left_ankle_roll_link.STL" />
      </geometry>
      <material name="">
        <color rgba="1 1 1 1" />
      </material>
    </visual>
    <collision>
      <origin xyz="0 0 0" rpy="0 0 0" />
      <geometry>
        <mesh filename="package://xbot_description/l3/meshes/left_ankle_roll_link.STL" />
      </geometry>
    </collision>
  </link>
  <joint name="left_ankle_roll_joint" type="revolute">
    <origin xyz="0 0 0" rpy="0 0 0" />
    <parent link="left_ankle_pitch_link" />
    <child link="left_ankle_roll_link" />
    <axis xyz="1.0 0.0 0.0" />
    <limit lower="-0.31" upper="0.31" effort="100.0" velocity="13.26" />
    <dynamics friction="0.666" />
  </joint>
 
  <link name="right_hip_roll_link">
    <inertial>
      <origin xyz="-0.0016523 6.6007E-06 0.003973" rpy="0 0 0" />
      <mass value="1.6446" />
      <inertia ixx="0.0023" ixy="-4.1132E-08" ixz="1.953E-05" iyy="0.0024" iyz="-6.1327E-07" izz="0.0031" />
    </inertial>
    <visual>
      <origin xyz="0 0 0" rpy="0 0 0" />
      <geometry>
        <mesh filename="package://xbot_description/l3/meshes/right_hip_roll_link.STL" />
      </geometry>
      <material name="">
        <color rgba="0.75294 0.75294 0.75294 1" />
      </material>
    </visual>
    <collision>
      <origin xyz="0 0 0" rpy="0 0 0" />
      <geometry>
        <mesh filename="package://xbot_description/l3/meshes/right_hip_roll_link.STL" />
      </geometry>
    </collision>
  </link>
  <joint name="right_hip_roll_joint" type="revolute">
    <origin xyz="0 -0.115 -0.079" rpy="0 0 0" />
    <parent link="waist_yaw_link" />
    <child link="right_hip_roll_link" />
    <axis xyz="1.0 0.0 0.0" />
    <limit lower="-1.22" upper="0.21" effort="255.0" velocity="7.28" />
    <dynamics friction="1.444" />
  </joint>
  <link name="right_hip_yaw_link">
    <inertial>
      <origin xyz="-0.00055103 0.036441 -0.13872" rpy="0 0 0" />
      <mass value="3.9259" />
      <inertia ixx="0.0108" ixy="-0.0001" ixz="-1.1516E-05" iyy="0.0163" iyz="-0.0007" izz="0.0088" />
    </inertial>
    <visual>
      <origin xyz="0 0 0" rpy="0 0 0" />
      <geometry>
        <mesh filename="package://xbot_description/l3/meshes/right_hip_yaw_link.STL" />
      </geometry>
      <material name="">
        <color rgba="0.75294 0.75294 0.75294 1" />
      </material>
    </visual>
    <collision>
      <origin xyz="0 0 0" rpy="0 0 0" />
      <geometry>
        <mesh filename="package://xbot_description/l3/meshes/right_hip_yaw_link.STL" />
      </geometry>
    </collision>
  </link>
  <joint name="right_hip_yaw_joint" type="revolute">
    <origin xyz="0 0 0" rpy="0 0 0" />
    <parent link="right_hip_roll_link" />
    <child link="right_hip_yaw_link" />
    <axis xyz="0.0 0.0 1.0" />
    <limit lower="-1.22" upper="0.52" effort="100.0" velocity="13.26" />
    <dynamics friction="1.333" />
  </joint>
  <link name="right_hip_pitch_link">
    <inertial>
      <origin xyz="0.001563 -0.037227 -0.029942" rpy="0 0 0" />
      <mass value="4.6841" />
      <inertia ixx="0.0422" ixy="0.0002" ixz="-0.002" iyy="0.0469" iyz="-0.0055" izz="0.0121" />
    </inertial>
    <visual>
      <origin xyz="0 0 0" rpy="0 0 0" />
      <geometry>
        <mesh filename="package://xbot_description/l3/meshes/right_hip_pitch_link.STL" />
      </geometry>
      <material name="">
        <color rgba="0.75294 0.75294 0.75294 1" />
      </material>
    </visual>
    <collision>
      <origin xyz="0 0 0" rpy="0 0 0" />
      <geometry>
        <mesh filename="package://xbot_description/l3/meshes/right_hip_pitch_link.STL" />
      </geometry>
    </collision>
  </link>
  <joint name="right_hip_pitch_joint" type="revolute">
    <origin xyz="0 0.01 -0.144" rpy="0 -0.5236 0" />
    <parent link="right_hip_yaw_link" />
    <child link="right_hip_pitch_link" />
    <axis xyz="0.0 1.0 0.0" />
    <limit lower="-1.57" upper="1.4" effort="400.0" velocity="24.94" />
    <dynamics friction="1.555" />
  </joint>
  <link name="right_knee_link">
    <inertial>
      <origin xyz="0.01895 -4.8931E-06 -0.11968" rpy="0 0 0" />
      <mass value="2.1362" />
      <inertia ixx="0.0182" ixy="1.3108E-06" ixz="0.0005" iyy="0.0183" iyz="-0.0001" izz="0.0019" />
    </inertial>
    <visual>
      <origin xyz="0 0 0" rpy="0 0 0" />
      <geometry>
        <mesh filename="package://xbot_description/l3/meshes/right_knee_link.STL" />
      </geometry>
      <material name="">
        <color rgba="0.75294 0.75294 0.75294 1" />
      </material>
    </visual>
    <collision>
      <origin xyz="0 0 0" rpy="0 0 0" />
      <geometry>
        <mesh filename="package://xbot_description/l3/meshes/right_knee_link.STL" />
      </geometry>
    </collision>
  </link>
  <joint name="right_knee_joint" type="revolute">
    <origin xyz="0 0 -0.36" rpy="0 1.0472 0" />
    <parent link="right_hip_pitch_link" />
    <child link="right_knee_link" />
    <axis xyz="0.0 1.0 0.0" />
    <limit lower="-1.1" upper="1.31" effort="400.0" velocity="24.94" />
    <dynamics friction="1.555" />
  </joint>
  <link name="right_ankle_pitch_link">
    <inertial>
      <origin xyz="0.00077711 1.5954E-09 -5.1139E-05" rpy="0 0 0" />
      <mass value="0.080248" />
      <inertia ixx="4.8112E-06" ixy="3.3221E-13" ixz="-2.5895E-09" iyy="5.5064E-06" iyz="-6.6456E-12" izz="6.4137E-06" />
    </inertial>
    <visual>
      <origin xyz="0 0 0" rpy="0 0 0" />
      <geometry>
        <mesh filename="package://xbot_description/l3/meshes/right_ankle_pitch_link.STL" />
      </geometry>
      <material name="">
        <color rgba="0.75294 0.75294 0.75294 1" />
      </material>
    </visual>
    <collision>
      <origin xyz="0 0 0" rpy="0 0 0" />
      <geometry>
        <mesh filename="package://xbot_description/l3/meshes/right_ankle_pitch_link.STL" />
      </geometry>
    </collision>
  </link>
  <joint name="right_ankle_pitch_joint" type="revolute">
    <origin xyz="0 0 -0.36" rpy="0 -0.5236 0" />
    <parent link="right_knee_link" />
    <child link="right_ankle_pitch_link" />
    <axis xyz="0.0 1.0 0.0" />
    <limit lower="-0.66" upper="1.22" effort="100.0" velocity="13.26" />
    <dynamics friction="0.666" />
  </joint>
  <link name="right_ankle_roll_link">
    <inertial>
      <origin xyz="0.03731 -1.4676E-06 -0.045803" rpy="0 0 0" />
      <mass value="0.85281" />
      <inertia ixx="0.0006" ixy="1.1631E-07" ixz="-0.0003" iyy="0.004" iyz="-1.3563E-08" izz="0.0042" />
    </inertial>
    <visual>
      <origin xyz="0 0 0" rpy="0 0 0" />
      <geometry>
        <mesh filename="package://xbot_description/l3/meshes/right_ankle_roll_link.STL" />
      </geometry>
      <material name="">
        <color rgba="0.75294 0.75294 0.75294 1" />
      </material>
    </visual>
    <collision>
      <origin xyz="0 0 0" rpy="0 0 0" />
      <geometry>
        <mesh filename="package://xbot_description/l3/meshes/right_ankle_roll_link.STL" />
      </geometry>
    </collision>
  </link>
  <joint name="right_ankle_roll_joint" type="revolute">
    <origin xyz="0 0 0" rpy="0 0 0" />
    <parent link="right_ankle_pitch_link" />
    <child link="right_ankle_roll_link" />
    <axis xyz="1.0 0.0 0.0" />
    <limit lower="-0.31" upper="0.31" effort="100.0" velocity="13.26" />
    <dynamics friction="0.666" />
  </joint>
  <link name="base_rs_link">
    <inertial>
      <origin xyz="0.047424 0.00014285 -0.0082421" rpy="0 0 0" />
      <mass value="0.076907" />
      <inertia ixx="8.6659E-06" ixy="9.2769E-08" ixz="9.2769E-08" iyy="9.4298E-05" iyz="9.2769E-08" izz="9.4996E-05" />
    </inertial>
    <visual>
      <origin xyz="0 0 0" rpy="0 0 0" />
      <geometry>
        <mesh filename="package://xbot_description/l3/meshes/base_rs_link.STL" />
      </geometry>
      <material name="">
        <color rgba="1 1 1 1" />
      </material>
    </visual>
    <collision>
      <origin xyz="0 0 0" rpy="0 0 0" />
      <geometry>
        <mesh filename="package://xbot_description/l3/meshes/base_rs_link.STL" />
      </geometry>
    </collision>
  </link>
  <joint name="base_rs_joint" type="fixed">
    <origin xyz="0.137441900948728 0.047500000000018 0.207680711884881" rpy="-2.35619449019235 0 -1.5707963267949" />
    <parent link="base_link" />
    <child link="base_rs_link" />
    <axis xyz="0.0 0.0 0.0" />
  </joint>

  <link name="left_arm_flange_link">
  </link> 
  <joint
    name="left_arm_flange_fixed_joint"
    type="fixed">
    <origin
      xyz="0.0 0.0 0.0"
      rpy="3.1415926 0.0 0.0" />
    <parent
      link="left_hand_base_link" />
    <child
      link="left_arm_flange_link" />
  </joint>
  <!--left hand -->  
  <link name="left_hand_link">
    <inertial>
      <origin xyz="-0.00718397232462035 -0.00342395518292698 -0.0584832405332602" rpy="0 0 0" />
      <mass value="0.529961023577223" />
      <inertia ixx="0.000480653113997558" ixy="5.6276926629699E-06" ixz="-4.05859709772904E-05" iyy="0.00067789113848308" iyz="-4.83494002678735E-06" izz="0.00034697306572534" />
    </inertial>
    <visual>
      <origin xyz="0 0 0" rpy="0 0 0" />
      <geometry>
        <mesh filename="package://xbot_description/l3/meshes/left_hand_link.STL" />
      </geometry>
      <material name="">
        <color rgba="0.866666666666667 0.866666666666667 0.890196078431372 1" />
      </material>
    </visual>
    <collision>
      <origin xyz="0 0 0" rpy="0 0 0" />
      <geometry>
        <mesh filename="package://xbot_description/l3/meshes/left_hand_link.STL" />
      </geometry>
    </collision>
  </link>
  <joint
    name="left_hand_fixed_joint"
    type="fixed">
    <origin
      xyz="0.0 0.0 0.0"
      rpy="0.0 0 0" />
    <parent
      link="left_hand_base_link" />
    <child
      link="left_hand_link" />
  </joint>
  <link name="left_hand_thumb_bend_link">
    <inertial>
      <origin xyz="0.0145290714760328 0.000901344264936247 -0.000127911758588877" rpy="0 0 0" />
      <mass value="0.0098553409170395" />
      <inertia ixx="5.42977914410068E-07" ixy="-1.16969836118924E-08" ixz="-3.74492329986334E-08" iyy="1.29130197093564E-06" iyz="-1.5496972766742E-09" izz="1.30457824480983E-06" />
    </inertial>
    <visual>
      <origin xyz="0 0 0" rpy="0 0 0" />
      <geometry>
        <mesh filename="package://xbot_description/l3/meshes/left_hand_thumb_bend_link.STL" />
      </geometry>
      <material name="">
        <color rgba="0.890196078431372 0.890196078431372 0.913725490196078 1" />
      </material>
    </visual>
    <collision>
      <origin xyz="0 0 0" rpy="0 0 0" />
      <geometry>
        <mesh filename="package://xbot_description/l3/meshes/left_hand_thumb_bend_link.STL" />
      </geometry>
    </collision>
  </link>
  <joint name="left_hand_thumb_bend_joint" type="revolute">
    <origin xyz="0.0228 -0.0095 -0.0305" rpy="0 0 0" />
    <parent link="left_hand_link" />
    <child link="left_hand_thumb_bend_link" />
    <axis xyz="0 0 -1" />
    <limit lower="0" upper="1.83" effort="1.1" velocity="8.63" />
    <dynamics damping="1" friction="1" />
  </joint>
  <link name="left_hand_thumb_rota_link1">
    <inertial>
      <origin xyz="0.0279279151977349 0.000121046050863875 -0.000277543472497595" rpy="0 0 0" />
      <mass value="0.153197010050709" />
      <inertia ixx="2.41523784234409E-05" ixy="6.62856100469595E-06" ixz="1.88729265232125E-07" iyy="4.7191218462316E-05" iyz="1.13949521391224E-07" izz="5.6212272955421E-05" />
    </inertial>
    <visual>
      <origin xyz="0 0 0" rpy="0 0 0" />
      <geometry>
        <mesh filename="package://xbot_description/l3/meshes/left_hand_thumb_rota_link1.STL" />
      </geometry>
      <material name="">
        <color rgba="1 1 1 1" />
      </material>
    </visual>
    <collision>
      <origin xyz="0 0 0" rpy="0 0 0" />
      <geometry>
        <mesh filename="package://xbot_description/l3/meshes/left_hand_thumb_rota_link1.STL" />
      </geometry>
    </collision>
  </link>
  <joint name="left_hand_thumb_rota_joint1" type="revolute">
    <origin xyz="0.028599 -0.0083177 0.00178" rpy="-0.2618 0 -0.0407" />
    <parent link="left_hand_thumb_bend_link" />
    <child link="left_hand_thumb_rota_link1" />
    <axis xyz="0 1 0" />
    <limit lower="-1.05" upper="1.57" effort="1.1" velocity="8.63" />
    <dynamics damping="1" friction="1" />
  </joint>
  <link name="left_hand_thumb_rota_link2">
    <inertial>
      <origin xyz="0.0224529466888815 0.000690615200902365 0.00314278985524262" rpy="0 0 0" />
      <mass value="0.0374009578136616" />
      <inertia ixx="3.98060244076823E-06" ixy="4.94846156827651E-07" ixz="1.18267329781539E-07" iyy="8.21784089346997E-06" iyz="6.13556519818818E-08" izz="9.54038333156961E-06" />
    </inertial>
    <visual>
      <origin xyz="0 0 0" rpy="0 0 0" />
      <geometry>
        <mesh filename="package://xbot_description/l3/meshes/left_hand_thumb_rota_link2.STL" />
      </geometry>
      <material name="">
        <color rgba="0.384313725490196 0.384313725490196 0.384313725490196 1" />
      </material>
    </visual>
    <collision>
      <origin xyz="0 0 0" rpy="0 0 0" />
      <geometry>
        <mesh filename="package://xbot_description/l3/meshes/left_hand_thumb_rota_link2.STL" />
      </geometry>
    </collision>
  </link>
  <joint name="left_hand_thumb_rota_joint2" type="revolute">
    <origin xyz="0.0553 0 0" rpy="0 0 0" />
    <parent link="left_hand_thumb_rota_link1" />
    <child link="left_hand_thumb_rota_link2" />
    <axis xyz="0 1 0" />
    <limit lower="-0.17" upper="1.83" effort="0.4" velocity="14.38" />
    <dynamics damping="1" friction="1" />
  </joint>
  <link name="left_hand_thumb_rota_tip">
    <inertial>
      <origin xyz="2.77555756156289E-17 8.24456234185811E-09 0.000270106204327401" rpy="0 0 0" />
      <mass value="3.53429173528852E-08" />
      <inertia ixx="9.35114688295086E-14" ixy="-1.32725847303435E-28" ixz="9.86076131526265E-32" iyy="3.97607820219959E-14" iyz="-1.58322857389778E-21" izz="9.35114688295086E-14" />
    </inertial>
    <visual>
      <origin xyz="0 0 0" rpy="0 0 0" />
      <geometry>
        <mesh filename="package://xbot_description/l3/meshes/left_hand_thumb_rota_tip.STL" />
      </geometry>
      <material name="">
        <color rgba="0.698039215686274 0.698039215686274 0.698039215686274 1" />
      </material>
    </visual>
    <collision>
      <origin xyz="0 0 0" rpy="0 0 0" />
      <geometry>
        <mesh filename="package://xbot_description/l3/meshes/left_hand_thumb_rota_tip.STL" />
      </geometry>
    </collision>
  </link>
  <joint name="left_hand_thumb_rota_joint3" type="fixed">
    <origin xyz="0.0504017317642718 0 0" rpy="0 0 0" />
    <parent link="left_hand_thumb_rota_link2" />
    <child link="left_hand_thumb_rota_tip" />
    <axis xyz="0 0 0" />
  </joint>
  <link name="left_hand_index_bend_link">
    <inertial>
      <origin xyz="-0.000134544831370011 -0.000675884062860156 0.00420851049165961" rpy="0 0 0" />
      <mass value="0.0677836037392838" />
      <inertia ixx="2.16567127431793E-05" ixy="1.17519873383444E-08" ixz="-8.90740188704384E-08" iyy="2.09681513604224E-05" iyz="6.68676922531736E-07" izz="3.39515033610064E-06" />
    </inertial>
    <visual>
      <origin xyz="0 0 0" rpy="0 0 0" />
      <geometry>
        <mesh filename="package://xbot_description/l3/meshes/left_hand_index_bend_link.STL" />
      </geometry>
      <material name="">
        <color rgba="0.988235294117647 0.737254901960784 0.517647058823529 1" />
      </material>
    </visual>
    <collision>
      <origin xyz="0 0 0" rpy="0 0 0" />
      <geometry>
        <mesh filename="package://xbot_description/l3/meshes/left_hand_index_bend_link.STL" />
      </geometry>
    </collision>
  </link>
  <joint name="left_hand_index_bend_joint" type="revolute">
    <origin xyz="0.0265 -0.0065 -0.0899" rpy="0 0 0" />
    <parent link="left_hand_link" />
    <child link="left_hand_index_bend_link" />
    <axis xyz="0 1 0" />
    <limit lower="-0.175" upper="0.175" effort="0.4" velocity="14.38" />
    <dynamics damping="1" friction="1" />
  </joint>
  <link name="left_hand_index_rota_link1">
    <inertial>
      <origin xyz="0.000139769333493966 0.000800517079915854 -0.0356038561271479" rpy="0 0 0" />
      <mass value="0.0630216014538817" />
      <inertia ixx="2.0518746365106E-05" ixy="7.80218143369854E-09" ixz="-4.29054701209884E-07" iyy="1.92422615292432E-05" iyz="-2.4702784768408E-07" izz="4.15027341232346E-06" />
    </inertial>
    <visual>
      <origin xyz="0 0 0" rpy="0 0 0" />
      <geometry>
        <mesh filename="package://xbot_description/l3/meshes/left_hand_index_rota_link1.STL" />
      </geometry>
      <material name="">
        <color rgba="1 1 1 1" />
      </material>
    </visual>
    <collision>
      <origin xyz="0 0 0" rpy="0 0 0" />
      <geometry>
        <mesh filename="package://xbot_description/l3/meshes/left_hand_index_rota_link1.STL" />
      </geometry>
    </collision>
  </link>
  <joint name="left_hand_index_joint1" type="revolute">
    <origin xyz="0 0 -0.0178" rpy="0 0 0" />
    <parent link="left_hand_index_bend_link" />
    <child link="left_hand_index_rota_link1" />
    <axis xyz="-1 0 0" />
    <limit lower="0" upper="1.92" effort="1.1" velocity="8.63" />
    <dynamics damping="1" friction="1" />
  </joint>
  <link name="left_hand_index_rota_link2">
    <inertial>
      <origin xyz="0.000338569414886528 -1.93676040351407E-05 -0.0231328539120741" rpy="0 0 0" />
      <mass value="0.0179923076570599" />
      <inertia ixx="3.01810067223025E-06" ixy="-4.92126455642096E-10" ixz="-9.09991288403927E-08" iyy="3.0198354354144E-06" iyz="-5.99900012810543E-08" izz="9.885388987729E-07" />
    </inertial>
    <visual>
      <origin xyz="0 0 0" rpy="0 0 0" />
      <geometry>
        <mesh filename="package://xbot_description/l3/meshes/left_hand_index_rota_link2.STL" />
      </geometry>
      <material name="">
        <color rgba="0.866666666666667 0.866666666666667 0.890196078431372 1" />
      </material>
    </visual>
    <collision>
      <origin xyz="0 0 0" rpy="0 0 0" />
      <geometry>
        <mesh filename="package://xbot_description/l3/meshes/left_hand_index_rota_link2.STL" />
      </geometry>
    </collision>
  </link>
  <joint name="left_hand_index_joint2" type="revolute">
    <origin xyz="0 0 -0.0558" rpy="0 0 0" />
    <parent link="left_hand_index_rota_link1" />
    <child link="left_hand_index_rota_link2" />
    <axis xyz="-1 0 0" />
    <limit lower="0" upper="1.92" effort="0.4" velocity="14.38" />
    <dynamics damping="1" friction="1" />
  </joint>
  <link name="left_hand_index_rota_tip">
    <inertial>
      <origin xyz="9.47159017883337E-16 -1.66550800928533E-14 0" rpy="0 0 0" />
      <mass value="3.53429173528852E-08" />
      <inertia ixx="3.97607820219958E-14" ixy="2.06598273810657E-28" ixz="3.39655762044409E-26" iyy="9.35114688295087E-14" iyz="-1.30578596099644E-40" izz="9.35114688295087E-14" />
    </inertial>
    <visual>
      <origin xyz="0 0 0" rpy="0 0 0" />
      <geometry>
        <mesh filename="package://xbot_description/l3/meshes/left_hand_index_rota_tip.STL" />
      </geometry>
      <material name="">
        <color rgba="0.698039215686274 0.698039215686274 0.698039215686274 1" />
      </material>
    </visual>
    <collision>
      <origin xyz="0 0 0" rpy="0 0 0" />
      <geometry>
        <mesh filename="package://xbot_description/l3/meshes/left_hand_index_rota_tip.STL" />
      </geometry>
    </collision>
  </link>
  <joint name="left_hand_index_rota_joint3" type="fixed">
    <origin xyz="0 0 -0.0424999999999991" rpy="0 0 0" />
    <parent link="left_hand_index_rota_link2" />
    <child link="left_hand_index_rota_tip" />
    <axis xyz="0 0 0" />
  </joint>
  <link name="left_hand_mid_link1">
    <inertial>
      <origin xyz="0.000139769503048257 0.00080051681932813 -0.0356038562198462" rpy="0 0 0" />
      <mass value="0.0630216000876532" />
      <inertia ixx="2.0518746354026E-05" ixy="7.80206454050682E-09" ixz="-4.29054815974796E-07" iyy="1.92422617602022E-05" iyz="-2.47027801809116E-07" izz="4.15027323551749E-06" />
    </inertial>
    <visual>
      <origin xyz="0 0 0" rpy="0 0 0" />
      <geometry>
        <mesh filename="package://xbot_description/l3/meshes/left_hand_mid_link1.STL" />
      </geometry>
      <material name="">
        <color rgba="1 1 1 1" />
      </material>
    </visual>
    <collision>
      <origin xyz="0 0 0" rpy="0 0 0" />
      <geometry>
        <mesh filename="package://xbot_description/l3/meshes/left_hand_mid_link1.STL" />
      </geometry>
    </collision>
  </link>
  <joint name="left_hand_mid_joint1" type="revolute">
    <origin xyz="0.004 -0.0065 -0.1082" rpy="0 0 0" />
    <parent link="left_hand_link" />
    <child link="left_hand_mid_link1" />
    <axis xyz="-1 0 0" />
    <limit lower="0" upper="1.92" effort="1.1" velocity="8.63" />
    <dynamics damping="1" friction="1" />
  </joint>
  <link name="left_hand_mid_link2">
    <inertial>
      <origin xyz="0.000338571504924487 -1.93625114516685E-05 -0.0231328477388325" rpy="0 0 0" />
      <mass value="0.0179922971238626" />
      <inertia ixx="3.01809863607458E-06" ixy="-4.91830289601756E-10" ixz="-9.09984854679422E-08" iyy="3.01983397037226E-06" iyz="-5.99889522310673E-08" izz="9.88538040128258E-07" />
    </inertial>
    <visual>
      <origin xyz="0 0 0" rpy="0 0 0" />
      <geometry>
        <mesh filename="package://xbot_description/l3/meshes/left_hand_mid_link2.STL" />
      </geometry>
      <material name="">
        <color rgba="0.866666666666667 0.866666666666667 0.890196078431372 1" />
      </material>
    </visual>
    <collision>
      <origin xyz="0 0 0" rpy="0 0 0" />
      <geometry>
        <mesh filename="package://xbot_description/l3/meshes/left_hand_mid_link2.STL" />
      </geometry>
    </collision>
  </link>
  <joint name="left_hand_mid_joint2" type="revolute">
    <origin xyz="0 0 -0.0558" rpy="0 0 0" />
    <parent link="left_hand_mid_link1" />
    <child link="left_hand_mid_link2" />
    <axis xyz="-1 0 0" />
    <limit lower="0" upper="1.92" effort="0.4" velocity="14.38" />
    <dynamics damping="1" friction="1" />
  </joint>
  <link name="left_hand_mid_tip">
    <inertial>
      <origin xyz="3.46944695195361E-18 -6.27969898303604E-15 0" rpy="0 0 0" />
      <mass value="3.53429173528852E-08" />
      <inertia ixx="3.97607820219958E-14" ixy="2.08752389989043E-28" ixz="2.52777196678215E-29" iyy="9.35114688295087E-14" iyz="-1.79366203433577E-43" izz="9.35114688295086E-14" />
    </inertial>
    <visual>
      <origin xyz="0 0 0" rpy="0 0 0" />
      <geometry>
        <mesh filename="package://xbot_description/l3/meshes/left_hand_mid_tip.STL" />
      </geometry>
      <material name="">
        <color rgba="0.698039215686274 0.698039215686274 0.698039215686274 1" />
      </material>
    </visual>
    <collision>
      <origin xyz="0 0 0" rpy="0 0 0" />
      <geometry>
        <mesh filename="package://xbot_description/l3/meshes/left_hand_mid_tip.STL" />
      </geometry>
    </collision>
  </link>
  <joint name="left_hand_mid_joint3" type="fixed">
    <origin xyz="0 0 -0.0424999999999995" rpy="0 0 0" />
    <parent link="left_hand_mid_link2" />
    <child link="left_hand_mid_tip" />
    <axis xyz="0 0 0" />
  </joint>
  <link name="left_hand_ring_link1">
    <inertial>
      <origin xyz="0.000139769503829958 0.00080051746545018 -0.0356038550320788" rpy="0 0 0" />
      <mass value="0.0630216034004235" />
      <inertia ixx="2.05187480603073E-05" ixy="7.80204473072652E-09" ixz="-4.29055143702643E-07" iyy="1.92422630398686E-05" iyz="-2.47028634316192E-07" izz="4.15027377034858E-06" />
    </inertial>
    <visual>
      <origin xyz="0 0 0" rpy="0 0 0" />
      <geometry>
        <mesh filename="package://xbot_description/l3/meshes/left_hand_ring_link1.STL" />
      </geometry>
      <material name="">
        <color rgba="1 1 1 1" />
      </material>
    </visual>
    <collision>
      <origin xyz="0 0 0" rpy="0 0 0" />
      <geometry>
        <mesh filename="package://xbot_description/l3/meshes/left_hand_ring_link1.STL" />
      </geometry>
    </collision>
  </link>
  <joint name="left_hand_ring_joint1" type="revolute">
    <origin xyz="-0.016 -0.0065 -0.1052" rpy="0 0 0" />
    <parent link="left_hand_link" />
    <child link="left_hand_ring_link1" />
    <axis xyz="-1 0 0" />
    <limit lower="0" upper="1.92" effort="1.1" velocity="8.63" />
    <dynamics damping="1" friction="1" />
  </joint>
  <link name="left_hand_ring_link2">
    <inertial>
      <origin xyz="0.000338569362970571 -1.93675642107764E-05 -0.0231328537916428" rpy="0 0 0" />
      <mass value="0.0179923074393582" />
      <inertia ixx="3.01810064426992E-06" ixy="-4.92130070945092E-10" ixz="-9.09991388750487E-08" iyy="3.0198354064253E-06" iyz="-5.99899932123125E-08" izz="9.88538891512388E-07" />
    </inertial>
    <visual>
      <origin xyz="0 0 0" rpy="0 0 0" />
      <geometry>
        <mesh filename="package://xbot_description/l3/meshes/left_hand_ring_link2.STL" />
      </geometry>
      <material name="">
        <color rgba="0.866666666666667 0.866666666666667 0.890196078431372 1" />
      </material>
    </visual>
    <collision>
      <origin xyz="0 0 0" rpy="0 0 0" />
      <geometry>
        <mesh filename="package://xbot_description/l3/meshes/left_hand_ring_link2.STL" />
      </geometry>
    </collision>
  </link>
  <joint name="left_hand_ring_joint2" type="revolute">
    <origin xyz="0 0 -0.0558" rpy="0 0 0" />
    <parent link="left_hand_ring_link1" />
    <child link="left_hand_ring_link2" />
    <axis xyz="-1 0 0" />
    <limit lower="0" upper="1.92" effort="0.4" velocity="14.38" />
    <dynamics damping="1" friction="1" />
  </joint>
  <link name="left_hand_ring_tip">
    <inertial>
      <origin xyz="3.46944695195361E-18 -6.36816988031086E-15 0" rpy="0 0 0" />
      <mass value="3.53429173528852E-08" />
      <inertia ixx="3.97607820219958E-14" ixy="2.08752389989043E-28" ixz="2.52777196678215E-29" iyy="9.35114688295087E-14" iyz="-1.79366203433577E-43" izz="9.35114688295087E-14" />
    </inertial>
    <visual>
      <origin xyz="0 0 0" rpy="0 0 0" />
      <geometry>
        <mesh filename="package://xbot_description/l3/meshes/left_hand_ring_tip.STL" />
      </geometry>
      <material name="">
        <color rgba="0.698039215686274 0.698039215686274 0.698039215686274 1" />
      </material>
    </visual>
    <collision>
      <origin xyz="0 0 0" rpy="0 0 0" />
      <geometry>
        <mesh filename="package://xbot_description/l3/meshes/left_hand_ring_tip.STL" />
      </geometry>
    </collision>
  </link>
  <joint name="left_hand_ring_joint3" type="fixed">
    <origin xyz="0 0 -0.0425" rpy="0 0 0" />
    <parent link="left_hand_ring_link2" />
    <child link="left_hand_ring_tip" />
    <axis xyz="0 0 0" />
  </joint>
  <link name="left_hand_pinky_link1">
    <inertial>
      <origin xyz="0.000139769403140894 0.000800517208403269 -0.0356038550457389" rpy="0 0 0" />
      <mass value="0.0630216018833023" />
      <inertia ixx="2.05187477543832E-05" ixy="7.80212984947717E-09" ixz="-4.29055030397585E-07" iyy="1.92422628106822E-05" iyz="-2.47028571410968E-07" izz="4.15027354474908E-06" />
    </inertial>
    <visual>
      <origin xyz="0 0 0" rpy="0 0 0" />
      <geometry>
        <mesh filename="package://xbot_description/l3/meshes/left_hand_pinky_link1.STL" />
      </geometry>
      <material name="">
        <color rgba="1 1 1 1" />
      </material>
    </visual>
    <collision>
      <origin xyz="0 0 0" rpy="0 0 0" />
      <geometry>
        <mesh filename="package://xbot_description/l3/meshes/left_hand_pinky_link1.STL" />
      </geometry>
    </collision>
  </link>
  <joint name="left_hand_pinky_joint1" type="revolute">
    <origin xyz="-0.036 -0.0065 -0.1022" rpy="0 0 0" />
    <parent link="left_hand_link" />
    <child link="left_hand_pinky_link1" />
    <axis xyz="-1 0 0" />
    <limit lower="0" upper="1.92" effort="1.1" velocity="8.63" />
    <dynamics damping="1" friction="1" />
  </joint>
  <link name="left_hand_pinky_link2">
    <inertial>
      <origin xyz="0.000338573187645894 -1.93618349248192E-05 -0.0231328439241562" rpy="0 0 0" />
      <mass value="0.0179922893932107" />
      <inertia ixx="3.01809788005842E-06" ixy="-4.91751568021702E-10" ixz="-9.09983567107085E-08" iyy="3.0198329418105E-06" iyz="-5.99887920223039E-08" izz="9.8853806652991E-07" />
    </inertial>
    <visual>
      <origin xyz="0 0 0" rpy="0 0 0" />
      <geometry>
        <mesh filename="package://xbot_description/l3/meshes/left_hand_pinky_link2.STL" />
      </geometry>
      <material name="">
        <color rgba="0.866666666666667 0.866666666666667 0.890196078431372 1" />
      </material>
    </visual>
    <collision>
      <origin xyz="0 0 0" rpy="0 0 0" />
      <geometry>
        <mesh filename="package://xbot_description/l3/meshes/left_hand_pinky_link2.STL" />
      </geometry>
    </collision>
  </link>
  <joint name="left_hand_pinky_joint2" type="revolute">
    <origin xyz="0 0 -0.0558" rpy="0 0 0" />
    <parent link="left_hand_pinky_link1" />
    <child link="left_hand_pinky_link2" />
    <axis xyz="-1 0 0" />
    <limit lower="0" upper="1.92" effort="0.4" velocity="14.38" />
    <dynamics damping="1" friction="1" />
  </joint>
  <link name="left_hand_pinky_tip">
    <inertial>
      <origin xyz="1.38777878078145E-17 -8.99974539336768E-15 0" rpy="0 0 0" />
      <mass value="3.53429173528851E-08" />
      <inertia ixx="3.97607820219958E-14" ixy="2.08752389989043E-28" ixz="2.52777196678213E-29" iyy="9.35114688295085E-14" iyz="-1.79366203433577E-43" izz="9.35114688295085E-14" />
    </inertial>
    <visual>
      <origin xyz="0 0 0" rpy="0 0 0" />
      <geometry>
        <mesh filename="package://xbot_description/l3/meshes/left_hand_pinky_tip.STL" />
      </geometry>
      <material name="">
        <color rgba="0.698039215686274 0.698039215686274 0.698039215686274 1" />
      </material>
    </visual>
    <collision>
      <origin xyz="0 0 0" rpy="0 0 0" />
      <geometry>
        <mesh filename="package://xbot_description/l3/meshes/left_hand_pinky_tip.STL" />
      </geometry>
    </collision>
  </link>
  <joint name="left_hand_pinky_joint3" type="fixed">
    <origin xyz="0 0 -0.0424999999999995" rpy="0 0 0" />
    <parent link="left_hand_pinky_link2" />
    <child link="left_hand_pinky_tip" />
    <axis xyz="0 0 0" />
  </joint> 

    <link name="right_arm_flange_link">
    </link> 
  <joint
    name="right_arm_flange_fixed_joint"
    type="fixed">
    <origin
      xyz="0.0 0.0 0.0"
      rpy="3.1415926 0.0 0.0" />
    <parent
      link="right_hand_base_link" />
    <child
      link="right_arm_flange_link" />
  </joint>  
  <!--right hand-->  
  <link name="right_hand_link">
    <inertial>
      <origin xyz="-0.00713969600456059 0.00342243593256283 -0.0584806731230685" rpy="0 0 0" />
      <mass value="0.530025137189824" />
      <inertia ixx="0.000480675299127658" ixy="-5.70774350447044E-06" ixz="-3.94757992682007E-05" iyy="0.000677544052393642" iyz="4.84926198036181E-06" izz="0.000346610500441846" />
    </inertial>
    <visual>
      <origin xyz="0 0 0" rpy="0 0 0" />
      <geometry>
        <mesh filename="package://xbot_description/l3/meshes/right_hand_link.STL" />
      </geometry>
      <material name="">
        <color rgba="0.792156862745098 0.819607843137255 0.933333333333333 1" />
      </material>
    </visual>
    <collision>
      <origin xyz="0 0 0" rpy="0 0 0" />
      <geometry>
        <mesh filename="package://xbot_description/l3/meshes/right_hand_link.STL" />
      </geometry>
    </collision>
  </link> 
  <joint
    name="right_hand_fixed_joint"
    type="fixed">
    <origin
      xyz="0.0 0.0 0.0"
      rpy="0.0 0.0 0.0" />
    <parent
      link="right_hand_base_link" />
    <child
      link="right_hand_link" />
  </joint>  
  <link name="right_hand_thumb_bend_link">
    <inertial>
      <origin xyz="0.0145290801349471 -0.000901302744009009 -0.000127925728837824" rpy="0 0 0" />
      <mass value="0.0098552942780609" />
      <inertia ixx="5.42973961076784E-07" ixy="1.1697377817489E-08" ixz="-3.74480550329303E-08" iyy="1.29129949885877E-06" iyz="1.54918667172288E-09" izz="1.30457450474268E-06" />
    </inertial>
    <visual>
      <origin xyz="0 0 0" rpy="0 0 0" />
      <geometry>
        <mesh filename="package://xbot_description/l3/meshes/right_hand_thumb_bend_link.STL" />
      </geometry>
      <material name="">
        <color rgba="0.890196078431372 0.890196078431372 0.913725490196078 1" />
      </material>
    </visual>
    <collision>
      <origin xyz="0 0 0" rpy="0 0 0" />
      <geometry>
        <mesh filename="package://xbot_description/l3/meshes/right_hand_thumb_bend_link.STL" />
      </geometry>
    </collision>
  </link>
  <joint name="right_hand_thumb_bend_joint" type="revolute">
    <origin xyz="0.0228 0.0095 -0.0305" rpy="0 0 0" />
    <parent link="right_hand_link" />
    <child link="right_hand_thumb_bend_link" />
    <axis xyz="0 0 1" />
    <limit lower="0" upper="1.83" effort="1.1" velocity="8.63" />
    <dynamics damping="1" friction="1" />
  </joint>
  <link name="right_hand_thumb_rota_link1">
    <inertial>
      <origin xyz="0.0279237160722458 -0.000127602868102849 -0.000272577361780019" rpy="0 0 0" />
      <mass value="0.153264803291678" />
      <inertia ixx="2.4165365258545E-05" ixy="-6.63197358473128E-06" ixz="1.94475216115701E-07" iyy="4.72108607465942E-05" iyz="-1.01931561408839E-07" izz="5.62288901300273E-05" />
    </inertial>
    <visual>
      <origin xyz="0 0 0" rpy="0 0 0" />
      <geometry>
        <mesh filename="package://xbot_description/l3/meshes/right_hand_thumb_rota_link1.STL" />
      </geometry>
      <material name="">
        <color rgba="1 1 1 1" />
      </material>
    </visual>
    <collision>
      <origin xyz="0 0 0" rpy="0 0 0" />
      <geometry>
        <mesh filename="package://xbot_description/l3/meshes/right_hand_thumb_rota_link1.STL" />
      </geometry>
    </collision>
  </link>
  <joint name="right_hand_thumb_rota_joint1" type="revolute">
    <origin xyz="0.028599 0.0083177 0.00178" rpy="0.2618 0 0.0407" />
    <parent link="right_hand_thumb_bend_link" />
    <child link="right_hand_thumb_rota_link1" />
    <axis xyz="0 1 0" />
    <limit lower="-1.05" upper="1.57" effort="1.1" velocity="8.63" />
    <dynamics damping="1" friction="1" />
  </joint>
  <link name="right_hand_thumb_rota_link2">
    <inertial>
      <origin xyz="0.0224697187075982 -0.000691342225602463 0.00302232046900801" rpy="0 0 0" />
      <mass value="0.0374003730407777" />
      <inertia ixx="3.98187483395831E-06" ixy="-4.9463629774215E-07" ixz="1.48034880030095E-07" iyy="8.21760971089748E-06" iyz="-5.85388102153786E-08" izz="9.53856476569885E-06" />
    </inertial>
    <visual>
      <origin xyz="0 0 0" rpy="0 0 0" />
      <geometry>
        <mesh filename="package://xbot_description/l3/meshes/right_hand_thumb_rota_link2.STL" />
      </geometry>
      <material name="">
        <color rgba="0.792156862745098 0.819607843137255 0.933333333333333 1" />
      </material>
    </visual>
    <collision>
      <origin xyz="0 0 0" rpy="0 0 0" />
      <geometry>
        <mesh filename="package://xbot_description/l3/meshes/right_hand_thumb_rota_link2.STL" />
      </geometry>
    </collision>
  </link>
  <joint name="right_hand_thumb_rota_joint2" type="revolute">
    <origin xyz="0.0553 0 0" rpy="0 0 0" />
    <parent link="right_hand_thumb_rota_link1" />
    <child link="right_hand_thumb_rota_link2" />
    <axis xyz="0 1 0" />
    <limit lower="-0.175" upper="1.83" effort="0.4" velocity="14.38" />
    <dynamics damping="1" friction="1" />
  </joint>
  <link name="right_hand_thumb_rota_tip">
    <inertial>
      <origin xyz="8.28680735143195E-10 -8.2445667376474E-09 2.77555756156289E-16" rpy="0 0 0" />
      <mass value="3.53429173528852E-08" />
      <inertia ixx="9.35114688295028E-14" ixy="1.78168632222544E-20" ixz="5.02898827078395E-30" iyy="3.97607820220018E-14" iyz="-6.5475455133344E-29" izz="9.35114688295088E-14" />
    </inertial>
    <visual>
      <origin xyz="0 0 0" rpy="0 0 0" />
      <geometry>
        <mesh filename="package://xbot_description/l3/meshes/right_hand_thumb_rota_tip.STL" />
      </geometry>
      <material name="">
        <color rgba="0.698039215686274 0.698039215686274 0.698039215686274 1" />
      </material>
    </visual>
    <collision>
      <origin xyz="0 0 0" rpy="0 0 0" />
      <geometry>
        <mesh filename="package://xbot_description/l3/meshes/right_hand_thumb_rota_tip.STL" />
      </geometry>
    </collision>
  </link>
  <joint name="right_hand_thumb_rota_joint3" type="fixed">
    <origin xyz="0.0504024546888781 0 0" rpy="0 0 0" />
    <parent link="right_hand_thumb_rota_link2" />
    <child link="right_hand_thumb_rota_tip" />
    <axis xyz="0 0 0" />
  </joint>
  <link name="right_hand_index_bend_link">
    <inertial>
      <origin xyz="8.08448802515592E-05 0.000675884062860609 0.00420851049166139" rpy="0 0 0" />
      <mass value="0.0677836037392839" />
      <inertia ixx="2.16567127431793E-05" ixy="9.29177767371407E-09" ixz="2.1345292815894E-07" iyy="2.09689353738481E-05" iyz="-6.68676922531782E-07" izz="3.39593434952634E-06" />
    </inertial>
    <visual>
      <origin xyz="0 0 0" rpy="0 0 0" />
      <geometry>
        <mesh filename="package://xbot_description/l3/meshes/right_hand_index_bend_link.STL" />
      </geometry>
      <material name="">
        <color rgba="0.43921568627451 0.43921568627451 0.43921568627451 1" />
      </material>
    </visual>
    <collision>
      <origin xyz="0 0 0" rpy="0 0 0" />
      <geometry>
        <mesh filename="package://xbot_description/l3/meshes/right_hand_index_bend_link.STL" />
      </geometry>
    </collision>
  </link>
  <joint name="right_hand_index_bend_joint" type="revolute">
    <origin xyz="0.0265 0.0065 -0.0899" rpy="0 0 0" />
    <parent link="right_hand_link" />
    <child link="right_hand_index_bend_link" />
    <axis xyz="0 1 0" />
    <limit lower="-0.175" upper="0.175" effort="0.4" velocity="14.38" />
    <dynamics damping="1" friction="1" />
  </joint>
  <link name="right_hand_index_rota_link1">
    <inertial>
      <origin xyz="-0.000139769529292743 -0.0008005173406112 -0.0356038554391181" rpy="0 0 0" />
      <mass value="0.0630216027459696" />
      <inertia ixx="2.05187473304044E-05" ixy="7.80203520045171E-09" ixz="4.29054958401514E-07" iyy="1.92422623666435E-05" iyz="2.47028335879796E-07" izz="4.15027364465252E-06" />
    </inertial>
    <visual>
      <origin xyz="0 0 0" rpy="0 0 0" />
      <geometry>
        <mesh filename="package://xbot_description/l3/meshes/right_hand_index_rota_link1.STL" />
      </geometry>
      <material name="">
        <color rgba="1 1 1 1" />
      </material>
    </visual>
    <collision>
      <origin xyz="0 0 0" rpy="0 0 0" />
      <geometry>
        <mesh filename="package://xbot_description/l3/meshes/right_hand_index_rota_link1.STL" />
      </geometry>
    </collision>
  </link>
  <joint name="right_hand_index_joint1" type="revolute">
    <origin xyz="0 0 -0.0178" rpy="0 0 0" />
    <parent link="right_hand_index_bend_link" />
    <child link="right_hand_index_rota_link1" />
    <axis xyz="1 0 0" />
    <limit lower="0" upper="1.92" effort="1.1" velocity="8.63" />
    <dynamics damping="1" friction="1" />
  </joint>
  <link name="right_hand_index_rota_link2">
    <inertial>
      <origin xyz="-0.000338569409191088 1.93676000460963E-05 -0.0231328539090889" rpy="0 0 0" />
      <mass value="0.0179923076356481" />
      <inertia ixx="3.01810066952146E-06" ixy="-4.92126710010375E-10" ixz="9.0999129965313E-08" iyy="3.01983543305207E-06" iyz="5.99900021060723E-08" izz="9.88538897829343E-07" />
    </inertial>
    <visual>
      <origin xyz="0 0 0" rpy="0 0 0" />
      <geometry>
        <mesh filename="package://xbot_description/l3/meshes/right_hand_index_rota_link2.STL" />
      </geometry>
      <material name="">
        <color rgba="0.866666666666667 0.866666666666667 0.890196078431372 1" />
      </material>
    </visual>
    <collision>
      <origin xyz="0 0 0" rpy="0 0 0" />
      <geometry>
        <mesh filename="package://xbot_description/l3/meshes/right_hand_index_rota_link2.STL" />
      </geometry>
    </collision>
  </link>
  <joint name="right_hand_index_joint2" type="revolute">
    <origin xyz="0 0 -0.0558" rpy="0 0 0" />
    <parent link="right_hand_index_rota_link1" />
    <child link="right_hand_index_rota_link2" />
    <axis xyz="1 0 0" />
    <limit lower="0" upper="1.92" effort="0.4" velocity="14.38" />
    <dynamics damping="1" friction="1" />
  </joint>
  <link name="right_hand_index_rota_tip">
    <inertial>
      <origin xyz="-2.98372437868011E-16 4.86850143532891E-15 -2.77555756156289E-17" rpy="0 0 0" />
      <mass value="3.53429173528852E-08" />
      <inertia ixx="3.97607820219958E-14" ixy="4.31827422870135E-29" ixz="1.6690203866884E-29" iyy="9.35114688295087E-14" iyz="1.37887768889562E-41" izz="9.35114688295087E-14" />
    </inertial>
    <visual>
      <origin xyz="0 0 0" rpy="0 0 0" />
      <geometry>
        <mesh filename="package://xbot_description/l3/meshes/right_hand_index_rota_tip.STL" />
      </geometry>
      <material name="">
        <color rgba="0.698039215686274 0.698039215686274 0.698039215686274 1" />
      </material>
    </visual>
    <collision>
      <origin xyz="0 0 0" rpy="0 0 0" />
      <geometry>
        <mesh filename="package://xbot_description/l3/meshes/right_hand_index_rota_tip.STL" />
      </geometry>
    </collision>
  </link>
  <joint name="right_hand_index_rota_joint3" type="fixed">
    <origin xyz="0 0 -0.0424999999999993" rpy="0 0 0" />
    <parent link="right_hand_index_rota_link2" />
    <child link="right_hand_index_rota_tip" />
    <axis xyz="0 0 0" />
  </joint>
  <link name="right_hand_mid_link1">
    <inertial>
      <origin xyz="-0.000139769452255069 -0.000800516966578778 -0.0356038561997856" rpy="0 0 0" />
      <mass value="0.0630216005457211" />
      <inertia ixx="2.05187463723375E-05" ixy="7.80208491082156E-09" ixz="4.29054729251827E-07" iyy="1.92422616109533E-05" iyz="2.47027898316091E-07" izz="4.15027334868904E-06" />
    </inertial>
    <visual>
      <origin xyz="0 0 0" rpy="0 0 0" />
      <geometry>
        <mesh filename="package://xbot_description/l3/meshes/right_hand_mid_link1.STL" />
      </geometry>
      <material name="">
        <color rgba="1 1 1 1" />
      </material>
    </visual>
    <collision>
      <origin xyz="0 0 0" rpy="0 0 0" />
      <geometry>
        <mesh filename="package://xbot_description/l3/meshes/right_hand_mid_link1.STL" />
      </geometry>
    </collision>
  </link>
  <joint name="right_hand_mid_joint1" type="revolute">
    <origin xyz="0.004 0.0065 -0.1082" rpy="0 0 0" />
    <parent link="right_hand_link" />
    <child link="right_hand_mid_link1" />
    <axis xyz="1 0 0" />
    <limit lower="0" upper="1.92" effort="1.1" velocity="8.63" />
    <dynamics damping="1" friction="1" />
  </joint>
  <link name="right_hand_mid_link2">
    <inertial>
      <origin xyz="-0.000338569410644367 1.93676002657236E-05 -0.0231328539105626" rpy="0 0 0" />
      <mass value="0.0179923076388667" />
      <inertia ixx="3.01810066972044E-06" ixy="-4.92126597550988E-10" ixz="9.09991296960493E-08" iyy="3.01983543347029E-06" iyz="5.99900021064019E-08" izz="9.88538897954892E-07" />
    </inertial>
    <visual>
      <origin xyz="0 0 0" rpy="0 0 0" />
      <geometry>
        <mesh filename="package://xbot_description/l3/meshes/right_hand_mid_link2.STL" />
      </geometry>
      <material name="">
        <color rgba="0.866666666666667 0.866666666666667 0.890196078431372 1" />
      </material>
    </visual>
    <collision>
      <origin xyz="0 0 0" rpy="0 0 0" />
      <geometry>
        <mesh filename="package://xbot_description/l3/meshes/right_hand_mid_link2.STL" />
      </geometry>
    </collision>
  </link>
  <joint name="right_hand_mid_joint2" type="revolute">
    <origin xyz="0 0 -0.0558" rpy="0 0 0" />
    <parent link="right_hand_mid_link1" />
    <child link="right_hand_mid_link2" />
    <axis xyz="1 0 0" />
    <limit lower="0" upper="1.92" effort="0.4" velocity="14.38" />
    <dynamics damping="1" friction="1" />
  </joint>
  <link name="right_hand_mid_tip">
    <inertial>
      <origin xyz="8.67361737988404E-19 6.7992486640911E-15 -0.000393026889207115" rpy="0 0 0" />
      <mass value="3.53429173528852E-08" />
      <inertia ixx="3.97607820219958E-14" ixy="4.6998091400205E-29" ixz="1.72625026613961E-29" iyy="9.35114688295087E-14" iyz="-1.34632261157722E-30" izz="9.35114688295087E-14" />
    </inertial>
    <visual>
      <origin xyz="0 0 0" rpy="0 0 0" />
      <geometry>
        <mesh filename="package://xbot_description/l3/meshes/right_hand_mid_tip.STL" />
      </geometry>
      <material name="">
        <color rgba="0.698039215686274 0.698039215686274 0.698039215686274 1" />
      </material>
    </visual>
    <collision>
      <origin xyz="0 0 0" rpy="0 0 0" />
      <geometry>
        <mesh filename="package://xbot_description/l3/meshes/right_hand_mid_tip.STL" />
      </geometry>
    </collision>
  </link>
  <joint name="right_hand_mid_joint3" type="fixed">
    <origin xyz="0 0 -0.042107" rpy="0 0 0" />
    <parent link="right_hand_mid_link2" />
    <child link="right_hand_mid_tip" />
    <axis xyz="0 0 0" />
  </joint>
  <link name="right_hand_ring_link1">
    <inertial>
      <origin xyz="-0.000139769594263359 -0.000800517227339018 -0.0356038552802108" rpy="0 0 0" />
      <mass value="0.0630216021699602" />
      <inertia ixx="2.05187476755252E-05" ixy="7.80199293997393E-09" ixz="4.29055082722493E-07" iyy="1.92422628261764E-05" iyz="2.47028487672885E-07" izz="4.15027358505553E-06" />
    </inertial>
    <visual>
      <origin xyz="0 0 0" rpy="0 0 0" />
      <geometry>
        <mesh filename="package://xbot_description/l3/meshes/right_hand_ring_link1.STL" />
      </geometry>
      <material name="">
        <color rgba="1 1 1 1" />
      </material>
    </visual>
    <collision>
      <origin xyz="0 0 0" rpy="0 0 0" />
      <geometry>
        <mesh filename="package://xbot_description/l3/meshes/right_hand_ring_link1.STL" />
      </geometry>
    </collision>
  </link>
  <joint name="right_hand_ring_joint1" type="revolute">
    <origin xyz="-0.016 0.0065 -0.1052" rpy="0 0 0" />
    <parent link="right_hand_link" />
    <child link="right_hand_ring_link1" />
    <axis xyz="1 0 0" />
    <limit lower="0" upper="1.92" effort="1.1" velocity="8.63" />
    <dynamics damping="1" friction="1" />
  </joint>
  <link name="right_hand_ring_link2">
    <inertial>
      <origin xyz="-0.00033857292489315 1.9362209649449E-05 -0.0231328478093387" rpy="0 0 0" />
      <mass value="0.0179922978524175" />
      <inertia ixx="3.01809858290111E-06" ixy="-4.91620007394315E-10" ixz="9.09983307330798E-08" iyy="3.01983382489043E-06" iyz="5.99889823171253E-08" izz="9.88537681686488E-07" />
    </inertial>
    <visual>
      <origin xyz="0 0 0" rpy="0 0 0" />
      <geometry>
        <mesh filename="package://xbot_description/l3/meshes/right_hand_ring_link2.STL" />
      </geometry>
      <material name="">
        <color rgba="0.866666666666667 0.866666666666667 0.890196078431372 1" />
      </material>
    </visual>
    <collision>
      <origin xyz="0 0 0" rpy="0 0 0" />
      <geometry>
        <mesh filename="package://xbot_description/l3/meshes/right_hand_ring_link2.STL" />
      </geometry>
    </collision>
  </link>
  <joint name="right_hand_ring_joint2" type="revolute">
    <origin xyz="0 0 -0.0558" rpy="0 0 0" />
    <parent link="right_hand_ring_link1" />
    <child link="right_hand_ring_link2" />
    <axis xyz="1 0 0" />
    <limit lower="0" upper="1.92" effort="0.4" velocity="14.38" />
    <dynamics damping="1" friction="1" />
  </joint>
  <link name="right_hand_ring_tip">
    <inertial>
      <origin xyz="-6.93889390390723E-18 6.85042300663241E-15 0" rpy="0 0 0" />
      <mass value="3.53429173528852E-08" />
      <inertia ixx="3.97607820219958E-14" ixy="4.5336858465537E-29" ixz="1.6690203866884E-29" iyy="9.35114688295086E-14" iyz="1.38111976643854E-41" izz="9.35114688295086E-14" />
    </inertial>
    <visual>
      <origin xyz="0 0 0" rpy="0 0 0" />
      <geometry>
        <mesh filename="package://xbot_description/l3/meshes/right_hand_ring_tip.STL" />
      </geometry>
      <material name="">
        <color rgba="0.698039215686274 0.698039215686274 0.698039215686274 1" />
      </material>
    </visual>
    <collision>
      <origin xyz="0 0 0" rpy="0 0 0" />
      <geometry>
        <mesh filename="package://xbot_description/l3/meshes/right_hand_ring_tip.STL" />
      </geometry>
    </collision>
  </link>
  <joint name="right_hand_ring_joint3" type="fixed">
    <origin xyz="0 0 -0.0424999999999994" rpy="0 0 0" />
    <parent link="right_hand_ring_link2" />
    <child link="right_hand_ring_tip" />
    <axis xyz="0 0 0" />
  </joint>
  <link name="right_hand_pinky_link1">
    <inertial>
      <origin xyz="-0.000139769192568043 -0.000800516820207079 -0.035603856454747" rpy="0 0 0" />
      <mass value="0.0630215991316208" />
      <inertia ixx="2.05187455958907E-05" ixy="7.80222924483364E-09" ixz="4.29054564778114E-07" iyy="1.92422608092939E-05" iyz="2.47027716010302E-07" izz="4.15027320974138E-06" />
    </inertial>
    <visual>
      <origin xyz="0 0 0" rpy="0 0 0" />
      <geometry>
        <mesh filename="package://xbot_description/l3/meshes/right_hand_pinky_link1.STL" />
      </geometry>
      <material name="">
        <color rgba="1 1 1 1" />
      </material>
    </visual>
    <collision>
      <origin xyz="0 0 0" rpy="0 0 0" />
      <geometry>
        <mesh filename="package://xbot_description/l3/meshes/right_hand_pinky_link1.STL" />
      </geometry>
    </collision>
  </link>
  <joint name="right_hand_pinky_joint1" type="revolute">
    <origin xyz="-0.036 0.0065 -0.1022" rpy="0 0 0" />
    <parent link="right_hand_link" />
    <child link="right_hand_pinky_link1" />
    <axis xyz="1 0 0" />
    <limit lower="0" upper="1.92" effort="1.1" velocity="8.63" />
    <dynamics damping="1" friction="1" />
  </joint>
  <link name="right_hand_pinky_link2">
    <inertial>
      <origin xyz="-0.000338569414719665 1.93675989681556E-05 -0.0231328539159371" rpy="0 0 0" />
      <mass value="0.0179923076462156" />
      <inertia ixx="3.0181006709957E-06" ixy="-4.92126474056121E-10" ixz="9.0999128816634E-08" iyy="3.01983543495617E-06" iyz="5.99900018674419E-08" izz="9.88538897929235E-07" />
    </inertial>
    <visual>
      <origin xyz="0 0 0" rpy="0 0 0" />
      <geometry>
        <mesh filename="package://xbot_description/l3/meshes/right_hand_pinky_link2.STL" />
      </geometry>
      <material name="">
        <color rgba="0.866666666666667 0.866666666666667 0.890196078431372 1" />
      </material>
    </visual>
    <collision>
      <origin xyz="0 0 0" rpy="0 0 0" />
      <geometry>
        <mesh filename="package://xbot_description/l3/meshes/right_hand_pinky_link2.STL" />
      </geometry>
    </collision>
  </link>
  <joint name="right_hand_pinky_joint2" type="revolute">
    <origin xyz="0 0 -0.0558" rpy="0 0 0" />
    <parent link="right_hand_pinky_link1" />
    <child link="right_hand_pinky_link2" />
    <axis xyz="1 0 0" />
    <limit lower="0" upper="1.92" effort="0.4" velocity="14.38" />
    <dynamics damping="1" friction="1" />
  </joint>
  <link name="right_hand_pinky_tip">
    <inertial>
      <origin xyz="2.08166817117217E-17 9.41000749543619E-15 0" rpy="0 0 0" />
      <mass value="3.53429173528851E-08" />
      <inertia ixx="3.97607820219958E-14" ixy="4.31827422870134E-29" ixz="1.66902038668838E-29" iyy="9.35114688295085E-14" iyz="1.37887768889562E-41" izz="9.35114688295085E-14" />
    </inertial>
    <visual>
      <origin xyz="0 0 0" rpy="0 0 0" />
      <geometry>
        <mesh filename="package://xbot_description/l3/meshes/right_hand_pinky_tip.STL" />
      </geometry>
      <material name="">
        <color rgba="0.698039215686274 0.698039215686274 0.698039215686274 1" />
      </material>
    </visual>
    <collision>
      <origin xyz="0 0 0" rpy="0 0 0" />
      <geometry>
        <mesh filename="package://xbot_description/l3/meshes/right_hand_pinky_tip.STL" />
      </geometry>
    </collision>
  </link>
  <joint name="right_hand_pinky_joint3" type="fixed">
    <origin xyz="0 0 -0.0425" rpy="0 0 0" />
    <parent link="right_hand_pinky_link2" />
    <child link="right_hand_pinky_tip" />
    <axis xyz="0 0 0" />
  </joint> 
</robot>